Workbook

Sheet 0. Hướng dẫn
A1: EIDE — DANH MỤC USE CASE CHI TIẾT
A2: Đề án tốt nghiệp Thạc sĩ ngành Kỹ thuật Điện tử — Học viện Công nghệ Bưu chính Viễn thông (PTIT) · Học viên: Vũ Trí Công · Người hướng dẫn: TS. Nguyễn Trung Hiếu
A3: v1.2 (05/09/2026): thêm 11 use case nhóm I (kỹ nghệ), J (tri thức & dò tìm), K (tự tạo công cụ) — 56 UC; sheet 10 sơ đồ tuần tự Mermaid cho mọi UC; sheet 11 ánh xạ bước ↔ năng lực ↔ màn hình; cổng theo chính sách (APD-08/POL-17).
A4: Embedded IDE trên nền GEditor · Knowledge Plane cục bộ · Bộ hồ sơ HKW/EIDE v1.0 · 05/09/2026 · Người lập: Vũ Trí Công (hỗ trợ: Claude)
A6: Cách đọc bộ sổ tính này
A7: 1. Tác nhân & cổng — ai tham gia, cổng người nào tồn tại và đứng ở đâu.
A8: 2. Danh mục UC — mỗi dòng một use case: mục tiêu, kích hoạt, tiền/hậu điều kiện, cổng, tri thức sinh ra, ưu tiên (M/S/C), mốc (M0–M5), truy vết FR/UR, màn hình UI.
A9: 3. Luồng chính — từng bước của mỗi UC: làn (N = người, T = tác tử, K = Knowledge Plane, H = công cụ/phần cứng), hành động, đầu vào → đầu ra, cổng/ghi chú.
A10: 4. Luồng thay thế — điều kiện ngoại lệ và cách xử lý cho mỗi UC.
A11: 5. Kịch bản mẫu — tình huống anh nêu (một board mới, zip hỗn hợp, thiếu thông tin → tìm mạng có phê duyệt, dựng mô phỏng) ánh xạ thành chuỗi UC theo thời gian.
A12: 6. Truy vết — ma trận UC ↔ nhóm quy trình ↔ FR ↔ UR ↔ màn hình, kèm thống kê bằng công thức.
A14: Quy ước
... A23: 9. Đầu vào trống — quy tắc hội thoại chung D1–D8, 10 kịch bản 'đầu vào chưa có gì' (kiểm tra tồn tại → dùng luôn/nhân bản/tạo mới, mẫu tham chiếu, ảnh không tài liệu…), và bảng 'mô tả ở đâu' trong bộ hồ sơ.

Sheet 1. Tác nhân & cổng
A1: TÁC NHÂN
A2: Tác nhân | B2: Loại | C2: Vai trò
A3: Kỹ sư | B3: Người dùng chính | C3: Tạo dự án, nạp tài liệu, ra lệnh, phê duyệt tại mọi cổng, quan sát phần cứng
A4: Người phê duyệt | B4: Người dùng | C4: Có thể trùng kỹ sư; duyệt G-SRC/G-FACT/G1/G3/G4/G5; cấp quyền G-OPS
A5: Pack owner | B5: Người dùng | C5: Soạn skill, benchmark; kiểm định và phát hành gói
A6: Librarian | B6: Tác tử | C6: Phân loại, tìm nguồn, điều phối trích xuất, trả lời tra cứu có trích dẫn
A7: Cartographer | B7: Tác tử | C7: Dựng BoardPassport từ CAD/ảnh; kiểm xung đột chân
A8: Planner | B8: Tác tử | C8: Lập kế hoạch có trích dẫn; tự đánh giá đủ thông tin
A9: Coder | B9: Tác tử | C9: Sinh/sửa mã với hkw:fact cho mọi hằng số
A10: Reviewer | B10: Tác tử (khác hãng) | C10: Chấm CodePatch theo checklist Pack
A11: Tester | B11: Tác tử | C11: Sinh kịch bản, dựng mô phỏng, chạy SIL/HIL, benchmark, huy hiệu
A12: Debugger | B12: Tác tử | C12: Giả thuyết, thí nghiệm phân biệt, gói chứng cứ
A13: Knowledge Plane | B13: Hệ thống | C13: Store, đồ thị, cổng người, hooks, ledger, router mô hình
... A15: Nguồn ngoài | B15: Hệ thống ngoài | C15: Registry, kho hãng (SVD/ATDF), docs MCP, web
A17: CỔNG NGƯỜI (GATE)
A18: Mã | B18: Tên | C18: Đứng ở đâu
A19: G-SRC | B19: Chọn nguồn | C19: Trước khi tải/trích xuất bất kỳ tài liệu nào tìm được trên mạng hoặc registry
A20: G-FACT | B20: Duyệt fact | C20: Trước khi fact tầng bạc/đồng được dùng cho sinh mã; duyệt theo nhóm có ảnh cắt
A21: G1 | B21: Duyệt kế hoạch | C21: Trước khi viết mã
A22: G3 | B22: Duyệt merge | C22: Sau 4 cổng công cụ + reviewer khác hãng; trước khi mã vào nhánh chính
A23: G4 | B23: Xác nhận vật lý | C23: Người quan sát board (LED, chuyển động, số đo) trước khi tính năng passing
A24: G5 | B24: Duyệt bàn giao/phát hành | C24: Trước khi xuất báo cáo, đóng gói, publish
A25: G-OPS | B25: Cấp quyền thao tác nguy hiểm | C25: Nạp, xóa flash, ghi bộ nhớ, ghi fuse, cài phần mềm, tải tệp lớn — theo phiên

Sheet 2. Danh mục UC
A1: Mã UC | B1: Tên use case | C1: Nhóm / quy trình | D1: Tác nhân chính | E1: Tác nhân phụ | F1: Mục tiêu | G1: Kích hoạt | H1: Tiền điều kiện | I1: Hậu điều kiện | J1: Cổng người | K1: Tri thức sinh ra | L1: Ưu tiên | M1: Mốc | N1: FR liên quan | O1: UR liên quan | P1: Màn hình UI | Q1: Số bước | R1: Số luồng thay thế
A2: UC-A01 | B2: Tạo dự án mới | C2: A. Dự án & môi trường | D2: Kỹ sư | E2: Knowledge Plane | F2: Có một thư mục dự án với .hkw/, tệp tiến độ, cấu hình mô hình, sẵn sàng nhận tài liệu | G2: Kỹ sư bấm 'Dự án mới' hoặc chạy eide init | H2: EIDE đã cài; eide doctor cơ bản đạt | I2: Thư mục .hkw/ (store.sqlite, FEATURES.json, PROGRESS.md, models.yaml, constraints.yaml) được tạo và commit Git | J2: — | K2: K6 (dự án): tên, mô tả, ISA/chip/board nếu đã biết | L2: M | M2: M0 | N2: FR-GOV-03, FR-PSP-03 | O2: UR-QT-03, UR-QT-04 | P2: Tổng quan | Q2: 5 | R2: 2
A3: UC-A02 | B3: Khai báo hoặc suy ra chip / ISA / board của dự án | C3: A. Dự án & môi trường | D3: Kỹ sư | E3: Librarian, Knowledge Plane | F3: Dự án biết mình chạy trên tập lệnh nào, chip nào, mạch nào — hoặc biết là chưa biết và cần nhận tri thức | G3: Sau UC-A01 hoặc sau khi nhập tài liệu phát hiện chip | H3: Dự án đã tạo | I3: constraints.yaml có isa/chip/board (hoặc 'unknown' kèm AcquisitionRequest mở) | J3: G-FACT nếu suy ra từ tài liệu | K3: K1 ISA profile, K2 lõi (pin), K3 board (nếu có) | L3: M | M3: M0 | N3: FR-PSP-01, FR-BRD-01 | O3: UR-TT-02, UR-PK-03 | P3: Tổng quan / Hộ chiếu chip | Q3: 5 | R3: 2
A4: UC-A03 | B4: Khám phá, cài đặt và khóa toolchain (eide doctor) | C4: A. Dự án & môi trường | D4: Kỹ sư | E4: Knowledge Plane, Tool Layer | F4: Máy có đủ công cụ biên dịch/nạp/mô phỏng cho ISA của dự án, phiên bản được khóa để tái lập | G4: Sau UC-A02; hoặc khi một cổng công cụ báo thiếu công cụ; hoặc lệnh eide doctor | H4: ISA profile đã chọn (có toolchain manifest) | I4: tools.lock ghi tên/phiên bản/hash; báo cáo môi trường; công cụ tùy chọn được đánh dấu | J4: G-OPS cho mỗi lệnh cài | K4: K8 (môi trường), hồ sơ tái lập | L4: M | M4: M1 | N4: FR-GOV-04 | O4: UR-QT-05, UR-PK-05 | P4: Môi trường & báo cáo | Q4: 6 | R4: 3
A5: UC-A04 | B5: Cấu hình mô hình ngôn ngữ và chế độ cục bộ | C5: A. Dự án & môi trường | D5: Kỹ sư | E5: Knowledge Plane | F5: Chọn mô hình theo vai trò, ngân sách ngày, chế độ cục bộ (không gửi tài liệu ra ngoài) | G5: Lần đầu tạo dự án; dự án nhạy cảm; đổi nhà cung cấp | H5: models.yaml mặc định tồn tại | I5: models.yaml hợp lệ; router kiểm được ứng viên; egress-guard bật/tắt theo cấu hình | J5: — | K5: K8 chính sách mô hình | L5: M | M5: M0 | N5: FR-LLM-02, FR-AGT-04, FR-LLM-04 | O5: UR-MH-01, UR-MH-02, UR-MH-03 | P5: Mô hình & chi phí | Q5: 4 | R5: 2
A6: UC-A05 | B6: Nhập dự án mã nguồn có sẵn | C6: A. Dự án & môi trường | D6: Kỹ sư | E6: Librarian, Coder | F6: EIDE hiểu repo hiện có: quy ước, cấu trúc, lệnh build, các hằng số phần cứng đang dùng | G6: Kỹ sư mở một repo có sẵn | H6: Repo có mã C/C++/Rust | I6: CONVENTIONS.md; CodeUnit với USES/CITES sơ bộ; danh sách hằng số chưa có nguồn | J6: — | K6: K6 quy ước; đồ thị USES | L6: S | M6: M2 | N6: FR-PSP-05, FR-AGT-03 | O6: UR-MA-04, UR-QT-04 | P6: Mã nguồn | Q6: 4 | R6: 1
A7: UC-A06 | B7: Tiếp tục phiên làm việc | C7: A. Dự án & môi trường | D7: Kỹ sư | E7: Knowledge Plane | F7: Sau khi tắt máy/crash, mở lại dự án đúng trạng thái và biết việc tiếp theo | G7: Mở dự án | H7: .hkw/ tồn tại | I7: Trạng thái máy trạng thái, gate đang mở, FEATURES/PROGRESS được hiển thị; build known-good chạy lại | J7: — | K7: K7 (đọc) | L7: M | M7: M2 | N7: FR-GOV-03, NFR-04 | O7: UR-QT-03 | P7: Tổng quan | Q7: 4 | R7: 2
A8: UC-B01 | B8: Nhập gói tài liệu hỗn hợp (zip có mạch, ảnh, PDF, tệp linh tinh) | C8: B. Nhận tri thức | D8: Kỹ sư | E8: Librarian, Knowledge Plane | F8: Mọi tệp trong gói được mở, phân loại theo nội dung, xếp đường đi theo tầng tin cậy; không tệp nào bị 'bịa' thành tri thức | G8: Kỹ sư kéo thả zip/thư mục vào EIDE hoặc eide ingest | H8: Dự án đã tạo | I8: Bảng phân loại; hàng đợi trích xuất; các AcquisitionRequest cho tệp cần duyệt | J8: G-SRC (ngầm định: tệp do người đưa vào = đã chọn nguồn); G-FACT cho tầng bạc | K8: Source (hash, kind, tier) cho từng tệp | L8: M | M8: M1 | N8: FR-ACQ-01, FR-ACQ-05 | O8: UR-TT-01 | P8: Nhập tài liệu | Q8: 7 | R8: 4
A9: UC-B02 | B9: Suy ra chip / linh kiện từ tài liệu và ảnh | C9: B. Nhận tri thức | D9: Librarian | E9: Cartographer, Kỹ sư | F9: Từ tên tệp, nội dung PDF, ảnh board/schematic, xác định MCU và các linh kiện chính để biết cần hộ chiếu nào | G9: Sau UC-B01 khi dự án chưa khai báo chip, hoặc gói có linh kiện mới | H9: Bảng phân loại | I9: Danh sách 'chip/linh kiện phát hiện' với mức tin cậy; người xác nhận; tạo yêu cầu hộ chiếu cho từng cái | J9: G-FACT | K9: Đề xuất K2/K4 (đồng → chờ) | L9: M | M9: M1 | N9: FR-ACQ-04, FR-BRD-02 | O9: UR-MC-02, UR-TT-02 | P9: Nhập tài liệu / Hàng đợi xác nhận | Q9: 5 | R9: 1
A10: UC-B03 | B10: Nhập nguồn cấu trúc chính hãng (SVD / ATDF / EDC / header) | C10: B. Nhận tri thức | D10: Knowledge Plane | E10: Kỹ sư | F10: Bản đồ thanh ghi tầng vàng vào Passport Store bằng parser xác định, không cần duyệt từng fact | G10: Tệp vàng trong UC-B01; pull registry; khai báo chip | H10: Tệp hợp lệ | I10: ChipPassport <ns.part@ver> với fact reviewed; ledger; nếu đã có phiên bản khác → báo diff | J10: G-SRC (chọn phiên bản) khi có nhiều bản | K10: K2 lõi | L10: M | M10: M0 | N10: FR-ACQ-02, FR-PSP-01, FR-PSP-02 | O10: UR-TT-02, UR-TT-03 | P10: Hộ chiếu chip | Q10: 5 | R10: 2
A11: UC-B04 | B11: Trích xuất tri thức từ PDF (datasheet, reference manual, errata) | C11: B. Nhận tri thức | D11: Librarian | E11: Kỹ sư | F11: Bảng thanh ghi, thông số điện, timing, errata trở thành fact tầng bạc có trang/bbox/ảnh cắt, chờ duyệt | G11: Tệp PDF trong hàng đợi CONFIRMED | H11: PDF trích được văn bản (không phải ảnh scan) hoặc có OCR | I11: Fact NORMALIZED theo nhóm; ảnh cắt trong cache; AcquisitionRequest → EXTRACTED | J11: G-FACT (sau đó) | K11: K2′ (chip) hoặc K4 (ngoại vi ngoài) | L11: M | M11: M1 | N11: FR-ACQ-03, FR-ACQ-07 | O11: UR-TT-01, UR-TT-05 | P11: Hàng đợi xác nhận | Q11: 5 | R11: 3
A12: UC-B05 | B12: Trích xuất từ ảnh (schematic chụp, ảnh board, ảnh màn hình đo) | C12: B. Nhận tri thức | D12: Cartographer | E12: Kỹ sư | F12: Ảnh trở thành đề xuất có cấu trúc (net, linh kiện, giá trị) để người xác nhận | G12: Ảnh trong hàng đợi | H12: Mô hình thị giác khả dụng (đám mây hoặc cục bộ) | I12: Đề xuất tầng bạc/đồng chờ duyệt; không bao giờ tự thành fact | J12: G-FACT | K12: K3 (mạch) đề xuất | L12: S | M12: M2 | N12: FR-ACQ-04, FR-BRD-02 | O12: UR-MC-02 | P12: Hàng đợi xác nhận | Q12: 4 | R12: 1
A13: UC-B06 | B13: Nhập schematic KiCad và dựng hộ chiếu mạch | C13: B. Nhận tri thức | D13: Cartographer | E13: Kỹ sư | F13: BoardPassport có net, chân, linh kiện, bus, địa chỉ suy ra; ràng buộc điện; xung đột được phát hiện | G13: .kicad_sch trong gói | H13: kicad-cli có trên máy (UC-A03) | I13: BoardPassport NORMALIZED chờ duyệt; kg.conflicts chạy; constraints cho Coder | J13: G-FACT | K13: K3 | L13: M | M13: M2 | N13: FR-BRD-01, FR-BRD-03, FR-BRD-04 | O13: UR-MC-01, UR-MC-03, UR-MC-04 | P13: Hộ chiếu mạch | Q13: 5 | R13: 2
... A57: UC-K01 | B57: Tác tử tự viết công cụ khi thiếu năng lực | C57: K. Tự tạo công cụ (v1.2) | D57: Tác tử (Orchestrator, coder) | E57: Kỹ sư, Pack owner | F57: Một công cụ Python mới, có test, hiệu ứng khai báo, chạy trong sandbox theo chính sách, đăng ký thành năng lực tạm; sau khi chứng minh được thăng cấp | G57: Chuỗi không tìm được năng lực khớp; năng lực trả lỗi lặp; kỹ sư ra lệnh 'viết cho anh công cụ …' | H57: Dự án mở; coder khả dụng | I57: tool_id trong .eide/tools; Capability user.* trong registry; ledger; (tùy) đề xuất thăng cấp | J57: G-TOOL (POL-17 TOOL-*); tool.promote T2 | K57: K5 thủ tục (công cụ), K7 (CapabilityRun) | L57: M | M57: M1 | N57: FR-TOOL-01…10 | O57: UR-NL-06 | P57: Công cụ tự tạo | Q57: 8 | R57: 3

Sheet 3. Luồng chính
A1: Mã UC | B1: Tên use case | C1: Bước | D1: Làn | E1: Hành động | F1: Đầu vào | G1: Đầu ra | H1: Cổng / ghi chú | I1: Mức tự chủ (APD)
A2: UC-A01 | B2: Tạo dự án mới | C2: 1 | D2: N | E2: Ra lệnh bằng ngôn ngữ tự nhiên, ví dụ: 'Tạo dự án robot cân bằng từ thư mục ~/robot-kit, chip chưa rõ' (một câu; có thể kèm kéo thả) | F2: câu lệnh | H2: Lệnh | I2: Lệnh
A3: UC-A01 | B3: Tạo dự án mới | C3: 2 | D3: T | E3: Librarian suy ra tên dự án, mô tả, chip/board (nếu nêu), đường dẫn tài liệu từ câu lệnh; điền mọi tham số mặc định (mức tự chủ A3, mô hình, ngân sách) | F3: câu lệnh | G3: tham số dự án | I3: T1
A4: UC-A01 | B4: Tạo dự án mới | C4: 3 | D4: K | E4: Tạo .hkw/ với schema store, tệp mặc định, .gitignore; ghi ledger 'project.init' | F4: tham số | G4: .hkw/ | I4: T1
A5: UC-A01 | B5: Tạo dự án mới | C5: 4 | D5: K | E5: Nếu đã biết chip: pull hộ chiếu lõi từ registry/seed và ghim phiên bản vào constraints.yaml | F5: chip id | G5: pin | H5: UC-G04 | I5: T1
A6: UC-A01 | B6: Tạo dự án mới | C6: 5 | D6: T | E6: Nếu câu lệnh có tài liệu: tự chuyển sang UC-B01 ngay; nếu không: hỏi đúng một câu 'anh có tài liệu board không?' | I6: T1
A7: UC-A02 | B7: Khai báo hoặc suy ra chip / ISA / board của dự án | C7: 1 | D7: T | E7: Lấy mã chip từ câu lệnh nếu người nêu (ví dụ 'dùng STM32F411CE'); nếu không, suy ra từ tài liệu ở UC-B02 | F7: câu lệnh/tài liệu | G7: mã chip (đề xuất) | I7: T1
A8: UC-A02 | B8: Khai báo hoặc suy ra chip / ISA / board của dự án | C8: 2 | D8: K | E8: Tra passport.list; nếu có lõi → ghim; nếu không → tìm registry/seed (UC-B08) | F8: mã | G8: pin hoặc yêu cầu | I8: T1
A9: UC-A02 | B9: Khai báo hoặc suy ra chip / ISA / board của dự án | C9: 3 | D9: T | E9: Nếu bỏ trống: Librarian sẽ suy ra chip từ tài liệu (SVD/schematic/ảnh) ở UC-B02 và đề xuất; người xác nhận | F9: tài liệu | G9: đề xuất chip | H9: G-FACT | I9: T1*
A10: UC-A02 | B10: Khai báo hoặc suy ra chip / ISA / board của dự án | C10: 4 | D10: K | E10: Nạp ISA profile tương ứng (armv7e-m, avr8, rv32…) và toolchain manifest | F10: chip | G10: ISA | I10: T1
A11: UC-A02 | B11: Khai báo hoặc suy ra chip / ISA / board của dự án | C11: 5 | D11: K | E11: Ghi ledger; cập nhật thanh trạng thái 'Pin: …' | I11: T1
A12: UC-A03 | B12: Khám phá, cài đặt và khóa toolchain (eide doctor) | C12: 1 | D12: K | E12: Đọc toolchain manifest của ISA profile (tên, phiên bản tối thiểu, lệnh kiểm, cách cài theo hệ điều hành) | F12: manifest | G12: danh sách | I12: T1
A13: UC-A03 | B13: Khám phá, cài đặt và khóa toolchain (eide doctor) | C13: 2 | D13: H | E13: Chạy lệnh kiểm từng công cụ (which/--version); phát hiện probe USB | G13: có/thiếu/phiên bản | I13: T1
A14: UC-A03 | B14: Khám phá, cài đặt và khóa toolchain (eide doctor) | C14: 3 | D14: T | E14: Librarian tổng hợp: bắt buộc thiếu gì, tùy chọn thiếu gì, đề xuất lệnh cài theo hệ điều hành | F14: kết quả | G14: đề xuất | I14: T1
A15: UC-A03 | B15: Khám phá, cài đặt và khóa toolchain (eide doctor) | C15: 4 | D15: T | E15: Công cụ mở trong danh sách tin cậy: tự cài (T1); công cụ đóng/có license: hướng dẫn người cài (T3) | F15: đề xuất | G15: quyết định | H15: G-OPS | I15: T1*
A16: UC-A03 | B16: Khám phá, cài đặt và khóa toolchain (eide doctor) | C16: 5 | D16: H | E16: Cài; kiểm lại phiên bản; tính hash nhị phân | I16: T1
A17: UC-A03 | B17: Khám phá, cài đặt và khóa toolchain (eide doctor) | C17: 6 | D17: K | E17: Ghi tools.lock; ledger; cập nhật thanh trạng thái Toolchain | G17: tools.lock | I17: T1
A18: UC-A04 | B18: Cấu hình mô hình ngôn ngữ và chế độ cục bộ | C18: 1 | D18: T | E18: Áp cấu hình mặc định (Claude/Gemini theo vai trò, reviewer khác hãng, ngân sách 5 USD/ngày, online); chỉ hỏi khi người ra lệnh đổi ('dùng Gemini cho tất cả', 'ngân sách 2 USD') | F18: câu lệnh (tùy chọn) | G18: models.yaml | I18: T1
A19: UC-A04 | B19: Cấu hình mô hình ngôn ngữ và chế độ cục bộ | C19: 2 | D19: K | E19: Kiểm quy tắc different_vendor_from(coder); kiểm khóa API theo biến môi trường; kiểm mô hình cục bộ (Ollama) | F19: models.yaml | G19: cảnh báo | I19: T1
A20: UC-A04 | B20: Cấu hình mô hình ngôn ngữ và chế độ cục bộ | C20: 3 | D20: K | E20: Chạy bộ kiểm thử hợp đồng 5 ca trên các adapter khả dụng (không tốn nhiều token) | G20: báo cáo | I20: T1
A21: UC-A04 | B21: Cấu hình mô hình ngôn ngữ và chế độ cục bộ | C21: 4 | D21: K | E21: Lưu; ghi ledger; cập nhật thanh trạng thái (offline/online, chi phí) | I21: T1
A22: UC-A05 | B22: Nhập dự án mã nguồn có sẵn | C22: 1 | D22: T | E22: Librarian khảo sát repo: build system, thư mục, định dạng mã, README | F22: repo | G22: CONVENTIONS.md (đề xuất) | I22: T1
A23: UC-A05 | B23: Nhập dự án mã nguồn có sẵn | C23: 2 | D23: K | E23: Phân tích tĩnh: tìm địa chỉ/bit hằng số; ánh xạ vào hộ chiếu nếu có → CodeUnit CITES/USES | F23: mã | G23: đồ thị | I23: T1
A24: UC-A05 | B24: Nhập dự án mã nguồn có sẵn | C24: 3 | D24: T | E24: Báo cáo: N hằng số khớp hộ chiếu, M hằng số không nguồn (đề xuất mở UC-B07) | G24: báo cáo | I24: T1
A25: UC-A05 | B25: Nhập dự án mã nguồn có sẵn | C25: 4 | D25: N | E25: Xác nhận CONVENTIONS.md; quyết định có bổ sung hkw:fact vào mã cũ dần hay không | I25: T2
A26: UC-A06 | B26: Tiếp tục phiên làm việc | C26: 1 | D26: K | E26: Kiểm hash store (phát hiện ghi ngoài cổng); nạp đồ thị từ cache hoặc tái dựng | I26: T1
A27: UC-A06 | B27: Tiếp tục phiên làm việc | C27: 2 | D27: K | E27: Đọc PROGRESS.md, FEATURES.json, gate đang mở, quyền đã hết hạn | G27: tóm tắt | I27: T1
A28: UC-A06 | B28: Tiếp tục phiên làm việc | C28: 3 | D28: H | E28: Chạy build known-good để xác nhận môi trường còn đúng | G28: ToolReport | I28: T1
A29: UC-A06 | B29: Tiếp tục phiên làm việc | C29: 4 | D29: T | E29: Librarian tóm tắt 'lần trước dừng ở đâu, việc tiếp theo là gì' | I29: T1
A30: UC-B01 | B30: Nhập gói tài liệu hỗn hợp (zip có mạch, ảnh, PDF, tệp linh tinh) | C30: 1 | D30: N | E30: Đưa tài liệu: kéo thả zip/thư mục, hoặc nêu đường dẫn trong câu lệnh ('tài liệu ở ~/robot-kit') | F30: zip | H30: Lệnh | I30: Lệnh
A31: UC-B01 | B31: Nhập gói tài liệu hỗn hợp (zip có mạch, ảnh, PDF, tệp linh tinh) | C31: 2 | D31: K | E31: Mở nén đệ quy trong sandbox (≤ 5 cấp, ≤ 2 GB, chống zip-slip); tính sha256 từng tệp | F31: zip | G31: danh sách tệp | I31: T1
A32: UC-B01 | B32: Nhập gói tài liệu hỗn hợp (zip có mạch, ảnh, PDF, tệp linh tinh) | C32: 3 | D32: K | E32: Phân loại theo chữ ký nội dung: SVD/ATDF/EDC/header/kicad → vàng; PDF/DOCX/HTML/ảnh → bạc; văn bản tự do/diễn đàn → đồng; khác → bỏ qua | F32: tệp | G32: bảng phân loại | I32: T1
A33: UC-B01 | B33: Nhập gói tài liệu hỗn hợp (zip có mạch, ảnh, PDF, tệp linh tinh) | C33: 4 | D33: T | E33: Librarian tóm tắt: tệp nào sinh hộ chiếu ngay, tệp nào cần trích xuất + duyệt, tệp nào chỉ làm ngữ cảnh; phát hiện chip/board từ tên và nội dung | F33: bảng | G33: tóm tắt + đề xuất | I33: T1
A34: UC-B01 | B34: Nhập gói tài liệu hỗn hợp (zip có mạch, ảnh, PDF, tệp linh tinh) | C34: 5 | D34: K | E34: Tệp vàng: chạy parser ngay → hộ chiếu (UC-B03/UC-B06). Tệp bạc: tạo AcquisitionRequest CONFIRMED → chờ trích xuất (UC-B04/B05) | I34: T1
A35: UC-B01 | B35: Nhập gói tài liệu hỗn hợp (zip có mạch, ảnh, PDF, tệp linh tinh) | C35: 6 | D35: T | E35: Tự trích xuất mọi tệp bạc ngay (A3); người chỉ xem bảng và có thể loại tệp sau | I35: T1
A36: UC-B01 | B36: Nhập gói tài liệu hỗn hợp (zip có mạch, ảnh, PDF, tệp linh tinh) | C36: 7 | D36: K | E36: Ghi ledger; cập nhật hàng đợi xác nhận | I36: T1
A37: UC-B02 | B37: Suy ra chip / linh kiện từ tài liệu và ảnh | C37: 1 | D37: T | E37: Đọc tiêu đề PDF, mã đặt hàng, chuỗi 'STM32F411', 'BME280'; đọc nhãn linh kiện trên ảnh bằng mô hình thị giác | F37: tệp | G37: ứng viên linh kiện | I37: T1
A38: UC-B02 | B38: Suy ra chip / linh kiện từ tài liệu và ảnh | C38: 2 | D38: K | E38: Đối chiếu với hộ chiếu có sẵn / registry | G38: có/chưa có | I38: T1
A39: UC-B02 | B39: Suy ra chip / linh kiện từ tài liệu và ảnh | C39: 3 | D39: T | E39: Trình bảng: linh kiện, vai trò dự đoán (MCU, cảm biến, driver), nguồn suy ra, tin cậy | G39: bảng | I39: T1
A40: UC-B02 | B40: Suy ra chip / linh kiện từ tài liệu và ảnh | C40: 4 | D40: N | E40: Xác nhận/sửa từng dòng (ví dụ: 'U3 là MPU6050 chứ không phải MPU9250') | H40: G-FACT | I40: T2
...

Sheet 4. Luồng thay thế
A1: Mã UC | B1: Tên use case | C1: Mã luồng | D1: Điều kiện | E1: Xử lý
A2: UC-A01 | B2: Tạo dự án mới | C2: A1 | D2: Thư mục đã có .hkw/ | E2: Hỏi: mở dự án hiện có (UC-A06) hay khởi tạo lại (cần xác nhận, không xóa store)
A3: UC-A01 | B3: Tạo dự án mới | C3: A2 | D3: Chưa có mô hình nào cấu hình khóa API | E3: Chuyển sang chế độ cục bộ nếu có Ollama; nếu không, vẫn tạo dự án nhưng tác tử tạm tắt (chỉ nhập tri thức tầng vàng bằng parser)
A4: UC-A02 | B4: Khai báo hoặc suy ra chip / ISA / board của dự án | C4: A1 | D4: Chip tùy chỉnh (không có SVD/ATDF) | E4: Tạo ISA profile 'custom' + hướng dẫn kỹ sư cung cấp bản đồ thanh ghi (SVD/CSV/YAML) → UC-B03 với nguồn do người cung cấp
A5: UC-A02 | B5: Khai báo hoặc suy ra chip / ISA / board của dự án | C5: A2 | D5: Tài liệu nêu 2 chip khác nhau | E5: Hỏi người: chip chính nào; chip còn lại là ngoại vi ngoài hay MCU phụ
A6: UC-A03 | B6: Khám phá, cài đặt và khóa toolchain (eide doctor) | C6: A1 | D6: Toolchain đóng (XC8/IAR/Keil) | E6: Không tự cài; hướng dẫn tải từ hãng; chỉ kiểm sự có mặt và phiên bản
A7: UC-A03 | B7: Khám phá, cài đặt và khóa toolchain (eide doctor) | C7: A2 | D7: Không có mạng (offline) | E7: Chỉ kiểm; liệt kê gói cần tải thủ công kèm hash mong đợi
A8: UC-A03 | B8: Khám phá, cài đặt và khóa toolchain (eide doctor) | C8: A3 | D8: Phiên bản đã khóa khác phiên bản có trên máy | E8: Cảnh báo lệch; hỏi khóa lại hay cài đúng phiên bản cũ
A9: UC-A04 | B9: Cấu hình mô hình ngôn ngữ và chế độ cục bộ | C9: A1 | D9: offline_mode nhưng không có mô hình cục bộ | E9: Từ chối bật; đề nghị cài Ollama + qwen2.5-coder
A10: UC-A04 | B10: Cấu hình mô hình ngôn ngữ và chế độ cục bộ | C10: A2 | D10: Chỉ có một nhà cung cấp | E10: Cho phép nhưng ghi cảnh báo 'reviewer cùng hãng' vào ledger và thanh trạng thái
A11: UC-A05 | B11: Nhập dự án mã nguồn có sẵn | C11: A1 | D11: Repo dùng hệ sinh thái chưa có Pack (ví dụ PIC) | E11: Tạo Pack khung 'custom' và chỉ bật kiểm tĩnh + build qua lệnh do người khai báo
A12: UC-A06 | B12: Tiếp tục phiên làm việc | C12: A1 | D12: Hash store lệch | E12: Từ chối mở ở chế độ ghi; đề nghị tái dựng đồ thị và kiểm toán ledger
... A74: UC-K01 | B74: Tác tử tự viết công cụ khi thiếu năng lực | C74: A3 | D74: Đã có năng lực khớp ≥ 0,8 | E74: Không viết mới; dùng năng lực có sẵn và báo lý do

Sheet 5. Kịch bản mẫu
A1: Bước | B1: Việc xảy ra (kịch bản: board mới, zip hỗn hợp, thiếu thông tin, mô phỏng trước khi có board) | C1: Use case | D1: Ai | E1: Cổng người | F1: Kết quả / tri thức sinh ra
A2: 1 | B2: Tạo dự án 'robot-ctrl', chưa biết chip | C2: UC-A01, UC-A02 (bỏ trống chip) | D2: Kỹ sư | E2: — | F2: .hkw/ tạo; trạng thái 'chưa biết chip'
A3: 2 | B3: Kéo thả robot-kit.zip (schematic PDF + KiCad, ảnh board, datasheet BME280/MPU6050, README, vài tệp linh tinh) | C3: UC-B01 | D3: Kỹ sư, Librarian | E3: — | F3: Bảng phân loại: 1 KiCad (vàng-cấu trúc), 2 PDF (bạc), 3 ảnh (bạc), 4 tệp bỏ qua
A4: 3 | B4: Librarian suy ra MCU STM32F411CE và các linh kiện từ KiCad + PDF; người xác nhận | C4: UC-B02 | D4: Librarian, Kỹ sư | E4: G-FACT | F4: Danh sách linh kiện đã xác nhận; yêu cầu hộ chiếu cho STM32F411, BME280, MPU6050, A4988
A5: 4 | B5: Pull hộ chiếu lõi STM32F411 từ registry/seed (SVD chính hãng); ghim phiên bản | C5: UC-G03, UC-B03 | D5: Knowledge Plane | E5: G-SRC (chọn phiên bản) | F5: 13.439 fact vàng; pin st.stm32f411@1.1.0; ISA armv7e-m
A6: 5 | B6: Dựng BoardPassport từ KiCad; phát hiện xung đột PB3 | C6: UC-B06, UC-C01 | D6: Cartographer, Kỹ sư | E6: G-FACT | F6: 31 net; 1 xung đột được người chọn phương án
A7: 6 | B7: Trích xuất 2 PDF cảm biến; duyệt theo nhóm với ảnh cắt | C7: UC-B04, UC-B10 | D7: Librarian, Kỹ sư | E7: G-FACT | F7: 58 fact bạc reviewed cho BME280; 44 cho MPU6050
A8: 7 | B8: Thiếu: datasheet A4988 và công thức bù nhiệt tr.25 → yêu cầu; Librarian tìm registry → hãng → web; người chọn nguồn; tải; trích; duyệt | C8: UC-B07, UC-B08, UC-B09, UC-B04, UC-B10 | D8: Librarian, Kỹ sư | E8: G-SRC, G-FACT | F8: Nguồn A4988 (Allegro) tầng bạc; 12 fact reviewed; yêu cầu đóng
A9: 8 | B9: eide doctor: phát hiện thiếu Renode và probe-rs; người duyệt cài; khóa phiên bản | C9: UC-A03 | D9: Kỹ sư, Tool Layer | E9: G-OPS | F9: tools.lock
A10: 9 | B10: Cấu hình mô hình: coder gemini-flash, reviewer claude-sonnet; ngân sách 5 USD; chưa bật offline | C10: UC-A04 | D10: Kỹ sư | E10: — | F10: models.yaml
A11: 10 | B11: Tester dựng mô phỏng: .repl từ hộ chiếu, mock BME280/MPU6050/A4988, LED PB3, UART2 → console; firmware hello chạy | C11: UC-E01 | D11: Tester, Kỹ sư | E11: G-FACT (tham số mock), G-OPS (cài) | F11: sim/ sẵn sàng; ToolReport sim đạt
A12: 11 | B12: Mô hình plant robot 2 bánh với tham số người cung cấp | C12: UC-E02 | D12: Tester, Kỹ sư | E12: G-FACT | F12: Mô hình đã kiểm bằng nghiệm giải tích
... A18: 17 | B18: Benchmark; đóng gói hộ chiếu BME280/A4988 + skill; phát hành nội bộ; xuất báo cáo và ma trận Người–AI | C18: UC-G01, UC-G02, UC-G04 | D18: Pack owner, Kỹ sư | E18: G5 | F18: Gói .hkp; báo cáo

Sheet 6. Truy vết
A1: Mã UC | B1: Tên | C1: Nhóm | D1: Ưu tiên | E1: Mốc | F1: Cổng người | G1: FR | H1: UR | I1: Màn hình
A2: UC-A01 | B2: Tạo dự án mới | C2: A. Dự án & môi trường | D2: M | E2: M0 | F2: — | G2: FR-GOV-03, FR-PSP-03 | H2: UR-QT-03, UR-QT-04 | I2: Tổng quan
A3: UC-A02 | B3: Khai báo hoặc suy ra chip / ISA / board của dự án | C3: A. Dự án & môi trường | D3: M | E3: M0 | F3: G-FACT nếu suy ra từ tài liệu | G3: FR-PSP-01, FR-BRD-01 | H3: UR-TT-02, UR-PK-03 | I3: Tổng quan / Hộ chiếu chip
A4: UC-A03 | B4: Khám phá, cài đặt và khóa toolchain (eide doctor) | C4: A. Dự án & môi trường | D4: M | E4: M1 | F4: G-OPS cho mỗi lệnh cài | G4: FR-GOV-04 | H4: UR-QT-05, UR-PK-05 | I4: Môi trường & báo cáo
A5: UC-A04 | B5: Cấu hình mô hình ngôn ngữ và chế độ cục bộ | C5: A. Dự án & môi trường | D5: M | E5: M0 | F5: — | G5: FR-LLM-02, FR-AGT-04, FR-LLM-04 | H5: UR-MH-01, UR-MH-02, UR-MH-03 | I5: Mô hình & chi phí
A6: UC-A05 | B6: Nhập dự án mã nguồn có sẵn | C6: A. Dự án & môi trường | D6: S | E6: M2 | F6: — | G6: FR-PSP-05, FR-AGT-03 | H6: UR-MA-04, UR-QT-04 | I6: Mã nguồn
A7: UC-A06 | B7: Tiếp tục phiên làm việc | C7: A. Dự án & môi trường | D7: M | E7: M2 | F7: — | G7: FR-GOV-03, NFR-04 | H7: UR-QT-03 | I7: Tổng quan
A8: UC-B01 | B8: Nhập gói tài liệu hỗn hợp (zip có mạch, ảnh, PDF, tệp linh tinh) | C8: B. Nhận tri thức | D8: M | E8: M1 | F8: G-SRC (ngầm định: tệp do người đưa vào = đã chọn nguồn); G-FACT cho tầng bạc | G8: FR-ACQ-01, FR-ACQ-05 | H8: UR-TT-01 | I8: Nhập tài liệu
A9: UC-B02 | B9: Suy ra chip / linh kiện từ tài liệu và ảnh | C9: B. Nhận tri thức | D9: M | E9: M1 | F9: G-FACT | G9: FR-ACQ-04, FR-BRD-02 | H9: UR-MC-02, UR-TT-02 | I9: Nhập tài liệu / Hàng đợi xác nhận
A10: UC-B03 | B10: Nhập nguồn cấu trúc chính hãng (SVD / ATDF / EDC / header) | C10: B. Nhận tri thức | D10: M | E10: M0 | F10: G-SRC (chọn phiên bản) khi có nhiều bản | G10: FR-ACQ-02, FR-PSP-01, FR-PSP-02 | H10: UR-TT-02, UR-TT-03 | I10: Hộ chiếu chip
A11: UC-B04 | B11: Trích xuất tri thức từ PDF (datasheet, reference manual, errata) | C11: B. Nhận tri thức | D11: M | E11: M1 | F11: G-FACT (sau đó) | G11: FR-ACQ-03, FR-ACQ-07 | H11: UR-TT-01, UR-TT-05 | I11: Hàng đợi xác nhận
A12: UC-B05 | B12: Trích xuất từ ảnh (schematic chụp, ảnh board, ảnh màn hình đo) | C12: B. Nhận tri thức | D12: S | E12: M2 | F12: G-FACT | G12: FR-ACQ-04, FR-BRD-02 | H12: UR-MC-02 | I12: Hàng đợi xác nhận
... A46: UC-H04 | B46: Tác tử từ chối hoặc trả lời 'không biết' | C46: H. Tương tác tác tử | D46: M | E46: M0 | F46: — | G46: NFR-02 | H46: UQ-01 | I46: Trò chuyện
A49: THỐNG KÊ (công thức)
A50: Tổng số UC | B50: =COUNTA(A2:A46)
A51: UC bắt buộc (M) | B51: =COUNTIF(D2:D46,"M")
A52: UC nên có (S) | B52: =COUNTIF(D2:D46,"S")
A53: UC có cổng người | B53: =COUNTIF(F2:F46,"<>—")
A54: Theo nhóm →
A55: A. Dự án & môi trường | B55: =COUNTIF(C2:C46,"A. Dự án & môi trường")
A56: B. Nhận tri thức | B56: =COUNTIF(C2:C46,"B. Nhận tri thức")
A57: C. Mạch & tài nguyên | B57: =COUNTIF(C2:C46,"C. Mạch & tài nguyên")
A58: D. Kế hoạch & sinh mã | B58: =COUNTIF(C2:C46,"D. Kế hoạch & sinh mã")
A59: E. Mô phỏng | B59: =COUNTIF(C2:C46,"E. Mô phỏng")
A60: F. Xác minh & gỡ lỗi | B60: =COUNTIF(C2:C46,"F. Xác minh & gỡ lỗi")
A61: G. Chia sẻ & đánh giá | B61: =COUNTIF(C2:C46,"G. Chia sẻ & đánh giá")
A62: H. Tương tác tác tử | B62: =COUNTIF(C2:C46,"H. Tương tác tác tử")
A64: Theo mốc → | B64: Số UC | C64: Số bước luồng chính
A65: M0 | B65: =COUNTIF(E2:E46,"M0") | C65: =SUMIF('2. Danh mục UC'!M:M,"M0",'2. Danh mục UC'!Q:Q)
A66: M1 | B66: =COUNTIF(E2:E46,"M1") | C66: =SUMIF('2. Danh mục UC'!M:M,"M1",'2. Danh mục UC'!Q:Q)
A67: M2 | B67: =COUNTIF(E2:E46,"M2") | C67: =SUMIF('2. Danh mục UC'!M:M,"M2",'2. Danh mục UC'!Q:Q)
A68: M3 | B68: =COUNTIF(E2:E46,"M3") | C68: =SUMIF('2. Danh mục UC'!M:M,"M3",'2. Danh mục UC'!Q:Q)
A69: M4 | B69: =COUNTIF(E2:E46,"M4") | C69: =SUMIF('2. Danh mục UC'!M:M,"M4",'2. Danh mục UC'!Q:Q)
A70: M5 | B70: =COUNTIF(E2:E46,"M5") | C70: =SUMIF('2. Danh mục UC'!M:M,"M5",'2. Danh mục UC'!Q:Q)

Sheet 7. Phân loại 3 mức
A1: BA MỨC TỰ CHỦ (rút gọn từ bảng 4 nhóm ở Bước 3) — cộng với 'Lệnh': thao tác duy nhất của kỹ sư là ra lệnh bằng ngôn ngữ tự nhiên
A2: Mức | B2: Tên | C2: Đặc điểm để nhận biết | D2: Cách giao
A3: T1 | B3: AI làm trọn | C3: Lặp lại nhiều, quy tắc rõ, kết quả kiểm được bằng máy, sai sót nhỏ và hoàn tác được | D3: Giao AI; người xem báo cáo định kỳ và có nút hoàn tác. Tương đương APPROVE tự động trong EIDE-APD-08.
A4: T2 | B4: AI làm — người duyệt | C4: AI làm được toàn bộ nhưng kết quả ràng buộc trách nhiệm, tiền bạc, hoặc cần chuyên môn người để chọn giữa các phương án | D4: AI làm/chuẩn bị đủ, người có thẩm quyền ký duyệt hoặc chọn phương án trước khi có hiệu lực. Tương đương ASK.
A5: T3 | B5: Người làm | C5: Rủi ro vật lý, không hoàn tác, quyết định chiến lược, quan hệ, pháp lý; hoặc cần tay/mắt người trên phần cứng | D5: Người làm; AI chỉ cung cấp thông tin đầu vào, checklist, kịch bản.
A6: Lệnh | B6: Kỹ sư ra lệnh | C6: Điểm khởi đầu của mọi việc: một câu bằng ngôn ngữ tự nhiên, có thể bao trùm nhiều UC | D6: Không phải thao tác thủ công; tác tử suy ra tham số và chạy chuỗi UC theo chính sách A3
A8: PHÂN LOẠI CÔNG VIỆC CỦA EIDE
A9: Quy trình | B9: Công việc | C9: Mức | D9: Đặc điểm nhận biết (lý do xếp mức) | E9: Cách giao trong EIDE | F9: UC liên quan | G9: Cổng cũ (APD thay bằng chính sách)
A10: P0 Dự án & môi trường | B10: Tạo dự án, tệp tiến độ, cấu hình mặc định — theo một câu lệnh của kỹ sư | C10: T1 | D10: Quy tắc rõ, hoàn tác được; tham số suy ra từ câu lệnh | E10: Kỹ sư ra lệnh; tác tử suy ra tên/mô tả/chip/đường dẫn và làm hết | F10: UC-A01, UC-H01 | G10: —
A11: P0 Dự án & môi trường | B11: Suy ra chip/ISA/board từ tài liệu | C11: T1 | D11: Kiểm được bằng đối chiếu 2 nguồn (SVD + KiCad + PDF) | E11: Tự xác nhận khi ≥ 2 nguồn khớp; báo cáo | F11: UC-A02, UC-B02 | G11: G-FACT
A12: P0 Dự án & môi trường | B12: Chọn chip chính khi tài liệu nêu nhiều chip | C12: T2 | D12: Cần chuyên môn người | E12: AI đề xuất kèm lý do; người chọn | F12: UC-A02 | G12: G-FACT
A13: P0 Dự án & môi trường | B13: Kiểm và cài toolchain mở (gcc, probe-rs, Renode, kicad-cli) | C13: T1 | D13: Danh sách gói tin cậy, hoàn tác được | E13: Tự cài từ danh sách trắng; khóa phiên bản; báo cáo | F13: UC-A03 | G13: G-OPS
A14: P0 Dự án & môi trường | B14: Cài toolchain đóng/có license (XC8, IAR, Keil) | C14: T3 | D14: Ràng buộc license, tài khoản hãng | E14: AI hướng dẫn từng bước; người tải và cài | F14: UC-A03 | G14: G-OPS
A15: P0 Dự án & môi trường | B15: Cấu hình mô hình và ngân sách mặc định | C15: T1 | D15: Mặc định an toàn (5 USD/ngày); đổi bằng một câu lệnh | E15: Tự áp; người chỉ nói khi muốn khác | F15: UC-A04 | G15: —
A16: P0 Dự án & môi trường | B16: Tăng ngân sách vượt mặc định | C16: T2 | D16: Ràng buộc tiền bạc | E16: AI hỏi khi sắp hết; người quyết | F16: UC-H03 | G16: —
A17: P0 Dự án & môi trường | B17: Khảo sát repo có sẵn, sinh CONVENTIONS.md | C17: T1 | D17: Quy tắc rõ, không phá hoại | E17: Tự làm; người xem | F17: UC-A05 | G17: —
A18: P0 Dự án & môi trường | B18: Tiếp tục phiên, chạy build known-good | C18: T1 | D18: Lặp lại | E18: Tự động khi mở dự án | F18: UC-A06 | G18: —
A19: P1 Nhận tri thức | B19: Mở nén, phân loại tệp theo nội dung, tính hash | C19: T1 | D19: Quy tắc rõ, sandbox | E19: Tự động | F19: UC-B01 | G19: —
A20: P1 Nhận tri thức | B20: Nhập SVD/ATDF/EDC/header chính hãng | C20: T1 | D20: Parser xác định, tầng vàng | E20: Tự động; báo số fact | F20: UC-B03 | G20: —
... A63: Quản trị | B63: Dừng khẩn / hạ mức tự chủ | C63: T3 | D63: Quyết định của người | E63: Lệnh 'dừng' ở bất kỳ đâu | F63: APD §5 | G63: —
A65: THỐNG KÊ
A66: AI làm trọn | B66: =COUNTIF(C10:C63,"T1") | C66: =B66/COUNTA(C10:C63)
A67: AI làm — người duyệt | B67: =COUNTIF(C10:C63,"T2") | C67: =B67/COUNTA(C10:C63)
A68: Người làm | B68: =COUNTIF(C10:C63,"T3") | C68: =B68/COUNTA(C10:C63)
A69: Tổng công việc | B69: =COUNTA(C10:C63)

Sheet 8. Năng lực
A1: MỖI USE CASE = MỘT NĂNG LỰC (capability) MÀ TÁC TỬ GỌI ĐƯỢC — người dùng chỉ ra lệnh bằng ngôn ngữ tự nhiên; màn hình UI là nơi xem kết quả
A2: Mã UC | B2: Năng lực (tên gọi trong Engine / MCP) | C2: Tham số vào | D2: Kết quả ra | E2: Ví dụ câu lệnh kích hoạt (hoặc tự gọi) | F2: Màn hình xem kết quả | G2: Mức tự chủ (sheet 7)
A3: UC-A01 | B3: project.create | C3: name?, description?, docs_path?, chip?, autonomy=A3 | D3: project_id, .hkw/ | E3: "Tạo dự án robot cân bằng từ ~/robot-kit" | F3: Tổng quan | G3: T1
A4: UC-A02 | B4: project.set_target | C4: chip?|inferred, isa?, board? | D4: pins, isa profile | E4: "Board này dùng STM32F411, chip cảm biến BME280" | F4: Hộ chiếu chip | G4: T2
A5: UC-A03 | B5: env.doctor | C5: install=true, lock=true | D5: EnvReport, tools.lock | E5: "Chuẩn bị môi trường biên dịch và mô phỏng" | F5: Môi trường & báo cáo | G5: T3
A6: UC-A04 | B6: models.configure | C6: roles?, budget_usd?, offline? | D6: models.yaml | E6: "Dùng Gemini cho coder, ngân sách 3 USD/ngày" | F6: Mô hình & chi phí | G6: T1
A7: UC-A05 | B7: repo.survey | C7: path | D7: CONVENTIONS.md, code_units | E7: "Đây là repo cũ, hãy hiểu nó trước" | F7: Mã nguồn | G7: T1
A8: UC-A06 | B8: session.resume | C8: — | D8: summary, next_action | E8: (tự động khi mở) / "Hôm qua dừng ở đâu?" | F8: Tổng quan | G8: T1
A9: UC-B01 | B9: knowledge.ingest | C9: path|zip, tier_policy | D9: classification, requests[] | E9: "Nạp bộ tài liệu này" | F9: Nhập tài liệu | G9: T1
A10: UC-B02 | B10: knowledge.identify_parts | C10: sources[] | D10: parts[] {mpn, role, confidence} | E10: (tự gọi sau ingest) | F10: Nhập tài liệu | G10: T1
A11: UC-B03 | B11: passport.import_structured | C11: file (svd|atdf|edc|header) | D11: passport_id, facts | E11: (tự gọi) | F11: Hộ chiếu chip | G11: T1
A12: UC-B04 | B12: knowledge.extract_pdf | C12: source_id, sections? | D12: facts[] normalized | E12: (tự gọi) / "Đọc datasheet BME280" | F12: Hàng đợi xác nhận | G12: T1
A13: UC-B05 | B13: knowledge.extract_image | C13: image, schema | D13: proposals[] | E13: "Đọc ảnh schematic này" | F13: Hàng đợi xác nhận | G13: T2
... A47: UC-H04 | B47: agent.decline | C47: — | D47: answer + request | E47: (tự động) | F47: Trò chuyện | G47: T1

Sheet 9. Đầu vào trống
A1: QUY TẮC HỘI THOẠI CHUNG (EIDE-DPS-09) — áp dụng cho mọi năng lực
A2: Mã | B2: Quy tắc | C2: Nội dung | D2: Vì sao
A3: D1 | B3: Đối chiếu trạng thái trước khi hành động | C3: Mọi lệnh tạo/nạp/sinh đều đi qua bước 'grounding': tra dự án, hộ chiếu, board, feature, registry để biết cái người nói ĐÃ TỒN TẠI chưa (khớp tên gần đúng, mã chip, đường dẫn, thời gian gần nhất). | D3: Tránh tạo trùng; cho phép 'dùng luôn' thay vì làm lại.
A4: D2 | B4: Điền ô trống bằng mặc định trước, hỏi sau | C4: Tham số thiếu được điền bằng mặc định có căn cứ (mức A3, mô hình mặc định, ngân sách 5 USD, tên dự án từ câu lệnh). Chỉ hỏi khi không có mặc định hợp lý hoặc lựa chọn không hoàn tác được. | D4: Giảm số câu hỏi; mọi mặc định ghi vào ledger và có thể đổi bằng một câu.
A5: D3 | B5: Tối đa MỘT câu hỏi gộp cho mỗi lượt | C5: Nếu cần hỏi, gộp các điểm mơ hồ thành một câu có phương án đánh số và phương án mặc định được đánh dấu; im lặng quá T (cấu hình, ví dụ 2 phút) ⇒ chọn mặc định và báo. | D5: Người không bị hỏi dồn dập.
A6: D4 | B6: Đề xuất trước, làm ngay phần chắc chắn | C6: Khi đầu vào trống, tác tử đề xuất một kế hoạch ngắn (3–6 dòng) và LÀM NGAY những việc T1 không phụ thuộc quyết định (tạo khung dự án, tìm tài liệu tham khảo), song song với việc chờ câu trả lời. | D6: Không có thời gian chết.
A7: D5 | B7: Ưu tiên nguồn theo thứ tự: người nói > dự án hiện có > registry/mẫu tham chiếu > web | C7: Khi suy ra chip/board/linh kiện cho một ý tưởng (ví dụ 'robot hai bánh tự cân bằng'), tác tử tra mẫu tham chiếu trong registry trước, rồi mới tìm web, và luôn trình bày là ĐỀ XUẤT có nguồn. | D7: Nhất quán với KAD: tri thức có nguồn, K9 chỉ đề xuất.
A8: D6 | B8: Xác nhận bằng cách nói lại ý hiểu | C8: Trước một chuỗi dài, tác tử nói lại ý hiểu trong 1–2 câu ('Tôi hiểu là… tôi sẽ…') rồi làm; người có thể sửa bất cứ lúc nào, không cần bấm xác nhận. | D8: Giảm hiểu sai mà không thêm cổng.
A9: D7 | B9: Hành động hoàn tác được thì làm, không hoàn tác được thì hỏi | C9: Nguyên tắc của APD-08 áp dụng ngay trong hội thoại: tạo/sửa/nạp board lab làm ngay; xóa dự án, ghi đè dự án đang có, xóa flash ⇒ hỏi. | D9: —
A10: D8 | B10: Ghi nhớ lựa chọn để lần sau không hỏi lại | C10: Mỗi câu trả lời của người (ví dụ 'luôn tạo mới', 'dùng ST-Link') được ghi thành tùy chọn dự án/người dùng; lần sau tác tử áp dụng và chỉ nhắc 'áp dụng như lần trước'. | D10: Số câu hỏi giảm dần theo thời gian.
A12: KỊCH BẢN ĐẦU VÀO CHƯA CÓ GÌ — tác tử kiểm tra gì, làm gì, hỏi gì
A13: Mã | B13: Câu lệnh của kỹ sư | C13: Tác tử kiểm tra (grounding) | D13: Kết quả kiểm tra | E13: Tác tử làm / hỏi | F13: Câu hỏi mẫu (tối đa 1, có mặc định) | G13: Mặc định khi im lặng | H13: UC / năng lực
A14: Z-01 | B14: "Tạo cho anh dự án robot hai bánh tự cân bằng" | C14: Có dự án tên gần giống (robot, cân bằng, balance) trong workspace? Có mẫu tham chiếu (reference project) trong registry? Có board/hộ chiếu nào đang mở? | D14: Không có gì | E14: Nói lại ý hiểu; tạo khung dự án 'robot-2-banh-tu-can-bang'; tra registry mẫu 'self-balancing robot' → đề xuất kiến trúc phần cứng (MCU, IMU, driver động cơ, nguồn) có nguồn; liệt kê cần gì từ anh (board có sẵn? tài liệu?) | F14: "Tôi đã tạo dự án và đề xuất BOM tham chiếu (STM32F411 + MPU6050 + A4988 + 2 stepper, nguồn 12 V). Anh có board/tài liệu sẵn không, hay tôi dựng theo mẫu tham chiếu để mô phỏng trước? [1] Mẫu tham chiếu (mặc định) [2] Tôi gửi tài liệu" | G14: [1] dựng theo mẫu tham chiếu, mô phỏng trước | H14: UC-A01, UC-A02, UC-G03, UC-E01
A15: Z-02 | B15: (như Z-01) | C15: (như Z-01) | D15: Có dự án 'robot-ctrl' tạo 3 ngày trước, 5/8 feature passing | E15: Không tạo mới ngay; nói rõ đã có gì; đề nghị dùng tiếp, nhân bản, hoặc tạo mới | F15: "Đã có dự án robot-ctrl (03/09, 5/8 tính năng chạy được, board BlackPill F411). Anh muốn: [1] tiếp tục dự án đó (mặc định) [2] nhân bản thành dự án mới [3] tạo mới trống" | G15: [1] tiếp tục; nếu im lặng 2 phút ⇒ mở dự án cũ | H15: UC-A06, UC-A01
A16: Z-03 | B16: (như Z-01) | C16: (như Z-01) | D16: Có mẫu tham chiếu trong registry (ví dụ eide.ref.balancing-robot@1.2) đã kiểm định trên board | E16: Đề xuất khởi tạo từ mẫu: kéo hộ chiếu chip/board, skill, kịch bản mô phỏng, firmware mẫu; báo khác biệt nếu người nêu linh kiện khác | F16: "Registry có mẫu robot cân bằng đã kiểm định (STM32F411 + MPU6050). Dùng mẫu này làm điểm xuất phát chứ? [1] Có (mặc định) [2] Không, tôi có thiết kế riêng" | G16: [1] dùng mẫu | H16: UC-G03, UC-A01
A17: Z-04 | B17: "Tạo dự án cho board này" (kèm 1 ảnh board, không tài liệu) | C17: Nhận diện linh kiện trên ảnh; tra hộ chiếu theo nhãn chip đọc được; tra registry | D17: Đọc được 'STM32F411CEU6', 'MPU-6050'; không có schematic | E17: Tạo dự án; pull hộ chiếu chip; tạo BoardPassport ĐỀ XUẤT từ ảnh (tầng bạc, chờ duyệt); tìm schematic board phổ biến (BlackPill) trên registry/web; nêu rõ những gì chưa chắc | F17: "Tôi nhận ra STM32F411CEU6 (BlackPill) và MPU6050. Tôi dùng sơ đồ BlackPill chuẩn từ registry cho phần MCU; dây nối MPU6050 tôi đoán từ ảnh (SCL→PB6, SDA→PB7) — anh xác nhận hoặc gửi schematic sau cũng được." | G17: Dùng sơ đồ chuẩn + net đoán từ ảnh ở tầng bạc; không sinh mã chạm net đoán cho tới khi duyệt | H17: UC-B05, UC-B06, UC-B08
A18: Z-05 | B18: "Viết firmware đọc nhiệt độ" (chưa có dự án nào mở) | C18: Có dự án nào trong workspace? Dự án mở gần nhất? Có cảm biến nhiệt nào trong hộ chiếu? | D18: Không có dự án mở; có 2 dự án cũ | E18: Hỏi một câu gộp: dự án nào / board nào; nếu chỉ có một dự án có cảm biến nhiệt ⇒ chọn luôn và báo | F18: "Anh muốn làm trên dự án nào? [1] robot-ctrl (có BME280, mặc định) [2] weather-node [3] dự án mới" | G18: [1] dự án gần nhất có cảm biến phù hợp | H18: UC-H01, UC-D01
A19: Z-06 | B19: "Bắt đầu với chip ESP32-C3" (không board, không tài liệu) | C19: Hộ chiếu esp.esp32-c3 có trong store/registry? Pack rv32/ESP-IDF đã cài? | D19: Có hộ chiếu (seed), chưa cài ESP-IDF | E19: Tạo dự án; ghim hộ chiếu; chạy eide doctor cài ESP-IDF (T1, danh sách tin cậy); dựng mô phỏng QEMU/Renode; hỏi một câu về board devkit nếu cần chân cụ thể | F19: "Đã ghim hộ chiếu ESP32-C3 và đang cài ESP-IDF (~5 phút). Anh dùng devkit nào? [1] ESP32-C3-DevKitM-1 (mặc định) [2] board khác — gửi schematic sau" | G19: [1] devkit chính hãng | H19: UC-A02, UC-A03, UC-E01
A20: Z-07 | B20: "Làm hết đi" (sau khi thả zip, không nói gì thêm) | C20: Zip có gì? Suy ra được mục tiêu dự án từ README/tên tệp không? | D20: Có schematic, datasheet, README ghi 'balancing robot' | E20: Suy ra mục tiêu; đề xuất danh sách Feature (F-01…F-08) từ README + BOM; làm ngay tri thức, môi trường, mô phỏng; bắt đầu Feature không cần quyết định của người; gửi báo cáo tiến độ | F20: "Tôi hiểu mục tiêu là robot cân bằng. Tôi đề xuất 8 tính năng theo README và bắt đầu từ F-01 (clock/UART). PID (F-07) chạm động cơ nên tôi sẽ hỏi trước khi nạp lên board thật." | G20: Làm theo đề xuất; F-07 chờ G1 | H20: UC-B01, UC-D01, UC-D02, UC-E01
A21: Z-08 | B21: "Tạo dự án X" nhưng tên X trùng đúng một dự án đang có | C21: Dự án X tồn tại? | D21: Có, đang có mã và feature | E21: Không ghi đè (R4). Hỏi rõ. | F21: "Dự án X đã tồn tại (12 tệp, 3 tính năng). [1] Mở dự án đó (mặc định) [2] Tạo X-2 [3] Xóa và tạo lại (cần xác nhận rõ)" | G21: [1] mở; [3] chỉ khi người gõ đúng cụm 'xóa X' | H21: UC-A01, UC-A06
A22: Z-09 | B22: "Mô phỏng thử cái robot" (chưa có mô hình plant, chưa có tham số) | C22: Có sim/ chưa? Có mô hình plant chưa? Có tham số vật lý (khối lượng, bánh) trong hộ chiếu/README? | D22: Có sim nền tảng, chưa có plant | E22: Dựng plant với tham số MẶC ĐỊNH của mẫu tham chiếu (có nguồn), gắn nhãn 'tham số tạm', chạy ngay; đề nghị người cho số thật khi có | F22: "Tôi chạy với tham số của mẫu tham chiếu (0,8 kg, bánh 65 mm, tâm khối 60 mm). Kết quả chỉ định tính cho tới khi anh cho số thật của robot." | G22: Tham số mẫu, nhãn tạm | H22: UC-E02, UC-E03
A23: Z-10 | B23: "Nạp lên board" (không biết board nào nối máy) | C23: Cổng serial/probe nào đang có? Board có được đánh dấu lab? Artifact đã qua G3? | D23: Phát hiện ST-Link + STM32F411; board chưa đánh dấu lab; artifact đạt | E23: Vì board chưa đánh dấu lab ⇒ hỏi một lần và đề nghị đánh dấu để lần sau tự động | F23: "Tôi thấy ST-Link nối STM32F411. Board này có động cơ không? [1] Không — đánh dấu 'lab' và nạp tự động từ nay (mặc định) [2] Có động cơ — chỉ nạp khi anh cho phép từng lần" | G23: [1] nếu BoardPassport không có driver động cơ; ngược lại [2] | H23: UC-F01, UC-F02
A25: MÔ TẢ Ở ĐÂU TRONG BỘ HỒ SƠ
A26: Nội dung | B26: Nơi mô tả | C26: Lý do
A27: Quy tắc chung của hội thoại (D1–D8) | B27: Tài liệu riêng: EIDE-DPS-09 'Chính sách hội thoại và suy luận ý định' (mới) — là phần 'tầng hiểu lệnh' của Agent Runtime; SRS-02 thêm nhóm FR-DLG | C27: Vì áp dụng xuyên suốt mọi UC, không thuộc riêng UC nào
A28: Kiểm tra tồn tại / dùng luôn hay tạo mới | B28: Trong từng use case: cột 'Tiền điều kiện' + 'Luồng thay thế' (sheet 4) — mỗi UC tạo/sửa đều có luồng 'đã tồn tại'; và trong hợp đồng năng lực (sheet 8): mục 'grounding' của từng capability | C28: Là hành vi cụ thể của năng lực đó
A29: Kịch bản đầu vào trống (Z-01…Z-10) | B29: Sheet 9 này (kịch bản hội thoại) + BPD-06 quy trình P0 'Tiếp nhận lệnh' (mới) + STP-05 test case hội thoại (TC-DLG) | C29: Là ca kiểm thử hành vi, cần chạy lại khi đổi mô hình/prompt
A30: Câu hỏi mẫu, mặc định, thời gian chờ | B30: autonomy.yaml (defaults, ask_timeout) + prompts/ của vai trò Librarian/Planner (K5 thủ tục) + tùy chọn đã ghi nhớ trong .hkw/preferences.yaml | C30: Là tham số vận hành, đổi không cần sửa mã
A31: Mẫu tham chiếu (reference project) như 'robot cân bằng' | B31: Registry: gói kind=template (hộ chiếu + BOM + skill + kịch bản mô phỏng + firmware mẫu) — KAD-07 thêm loại tri thức K5′ 'mẫu dự án' | C31: Để 'đầu vào trống' vẫn có điểm xuất phát có nguồn

Sheet 10. Sequence (Mermaid)
A1: Mã UC | B1: Tên | C1: Mermaid sequenceDiagram (dán vào GEditor/DiagramView)
A2: UC-A01 | B2: Tạo dự án mới | C2: sequenceDiagram autonumber participant KyS as Kỹ sư participant TT as Tác tử participant KP as Knowledge Plane KyS->>TT: Ra lệnh bằng ngôn ngữ tự nhiên, ví dụ, 'Tạo dự án robot cân bằng từ thư mục ~/robot-kit, c [Lệnh] TT->>KP: Librarian suy ra tên dự án, mô tả, chip/board (nếu nêu), đường dẫn tài liệu từ câu lệnh, đ Note over KP: ra: tham số dự án KP->>TT: Tạo .hkw/ với schema store, tệp mặc định, .gitignore, ghi ledger 'project.init' Note over TT: ra: .hkw/ KP->>TT: Nếu đã biết chip, pull hộ chiếu lõi từ registry/seed và ghim phiên bản vào constraints.yam Note over TT: ra: pin TT->>KP: Nếu câu lệnh có tài liệu, tự chuyển sang UC-B01 ngay, nếu không, hỏi đúng một câu 'anh có
A3: UC-A02 | B3: Khai báo hoặc suy ra chip / ISA / board của dự án | C3: sequenceDiagram autonumber participant TT as Tác tử participant KP as Knowledge Plane TT->>KP: Lấy mã chip từ câu lệnh nếu người nêu (ví dụ 'dùng STM32F411CE'), nếu không, suy ra từ tài Note over KP: ra: mã chip (đề xuất) KP->>TT: Tra passport.list, nếu có lõi → ghim, nếu không → tìm registry/seed (UC-B08) Note over TT: ra: pin hoặc yêu cầu TT->>KP: Nếu bỏ trống, Librarian sẽ suy ra chip từ tài liệu (SVD/schematic/ảnh) ở UC-B02 và đề xuất [G-FACT] Note over KP: ra: đề xuất chip KP->>TT: Nạp ISA profile tương ứng (armv7e-m, avr8, rv32…) và toolchain manifest Note over TT: ra: ISA KP->>TT: Ghi ledger, cập nhật thanh trạng thái 'Pin, …'
A4: UC-A03 | B4: Khám phá, cài đặt và khóa toolchain (eide doctor) | C4: sequenceDiagram autonumber participant TT as Tác tử participant KP as Knowledge Plane participant HW as Công cụ/Phần cứng KP->>HW: Đọc toolchain manifest của ISA profile (tên, phiên bản tối thiểu, lệnh kiểm, cách cài theo Note over HW: ra: danh sách HW->>TT: Chạy lệnh kiểm từng công cụ (which/--version), phát hiện probe USB Note over TT: ra: có/thiếu/phiên bản TT->>KP: Librarian tổng hợp, bắt buộc thiếu gì, tùy chọn thiếu gì, đề xuất lệnh cài theo hệ điều hà Note over KP: ra: đề xuất TT->>HW: Công cụ mở trong danh sách tin cậy, tự cài (T1), công cụ đóng/có license, hướng dẫn người [G-OPS] Note over HW: ra: quyết định HW->>KP: Cài, kiểm lại phiên bản, tính hash nhị phân KP->>TT: Ghi tools.lock, ledger, cập nhật thanh trạng thái Toolchain Note over TT: ra: tools.lock
A5: UC-A04 | B5: Cấu hình mô hình ngôn ngữ và chế độ cục bộ | C5: sequenceDiagram autonumber participant TT as Tác tử participant KP as Knowledge Plane TT->>KP: Áp cấu hình mặc định (Claude/Gemini theo vai trò, reviewer khác hãng, ngân sách 5 USD/ngày Note over KP: ra: models.yaml KP->>TT: Kiểm quy tắc different_vendor_from(coder), kiểm khóa API theo biến môi trường, kiểm mô hìn Note over TT: ra: cảnh báo KP->>TT: Chạy bộ kiểm thử hợp đồng 5 ca trên các adapter khả dụng (không tốn nhiều token) Note over TT: ra: báo cáo KP->>TT: Lưu, ghi ledger, cập nhật thanh trạng thái (offline/online, chi phí)
A6: UC-A05 | B6: Nhập dự án mã nguồn có sẵn | C6: sequenceDiagram autonumber participant KyS as Kỹ sư participant TT as Tác tử participant KP as Knowledge Plane TT->>KP: Librarian khảo sát repo, build system, thư mục, định dạng mã, README Note over KP: ra: CONVENTIONS.md (đề xuất) KP->>TT: Phân tích tĩnh, tìm địa chỉ/bit hằng số, ánh xạ vào hộ chiếu nếu có → CodeUnit CITES/USES Note over TT: ra: đồ thị TT->>KyS: Báo cáo, N hằng số khớp hộ chiếu, M hằng số không nguồn (đề xuất mở UC-B07) Note over KyS: ra: báo cáo KyS->>KP: Xác nhận CONVENTIONS.md, quyết định có bổ sung hkw,fact vào mã cũ dần hay không
A7: UC-A06 | B7: Tiếp tục phiên làm việc | C7: sequenceDiagram autonumber participant TT as Tác tử participant KP as Knowledge Plane participant HW as Công cụ/Phần cứng KP->>TT: Kiểm hash store (phát hiện ghi ngoài cổng), nạp đồ thị từ cache hoặc tái dựng KP->>HW: Đọc PROGRESS.md, FEATURES.json, gate đang mở, quyền đã hết hạn Note over HW: ra: tóm tắt HW->>TT: Chạy build known-good để xác nhận môi trường còn đúng Note over TT: ra: ToolReport TT->>KP: Librarian tóm tắt 'lần trước dừng ở đâu, việc tiếp theo là gì'
A8: UC-B01 | B8: Nhập gói tài liệu hỗn hợp (zip có mạch, ảnh, PDF, tệp linh tinh) | C8: sequenceDiagram autonumber participant KyS as Kỹ sư participant TT as Tác tử participant KP as Knowledge Plane KyS->>KP: Đưa tài liệu, kéo thả zip/thư mục, hoặc nêu đường dẫn trong câu lệnh ('tài liệu ở ~/robot- [Lệnh] KP->>TT: Mở nén đệ quy trong sandbox (≤ 5 cấp, ≤ 2 GB, chống zip-slip), tính sha256 từng tệp Note over TT: ra: danh sách tệp KP->>TT: Phân loại theo chữ ký nội dung, SVD/ATDF/EDC/header/kicad → vàng, PDF/DOCX/HTML/ảnh → bạc, Note over TT: ra: bảng phân loại TT->>KP: Librarian tóm tắt, tệp nào sinh hộ chiếu ngay, tệp nào cần trích xuất + duyệt, tệp nào chỉ Note over KP: ra: tóm tắt + đề xuất KP->>TT: Tệp vàng, chạy parser ngay → hộ chiếu (UC-B03/UC-B06). Tệp bạc, tạo AcquisitionRequest CON TT->>KP: Tự trích xuất mọi tệp bạc ngay (A3), người chỉ xem bảng và có thể loại tệp sau KP->>TT: Ghi ledger, cập nhật hàng đợi xác nhận
A9: UC-B02 | B9: Suy ra chip / linh kiện từ tài liệu và ảnh | C9: sequenceDiagram autonumber participant KyS as Kỹ sư participant TT as Tác tử participant KP as Knowledge Plane TT->>KP: Đọc tiêu đề PDF, mã đặt hàng, chuỗi 'STM32F411', 'BME280', đọc nhãn linh kiện trên ảnh bằn Note over KP: ra: ứng viên linh kiện KP->>TT: Đối chiếu với hộ chiếu có sẵn / registry Note over TT: ra: có/chưa có TT->>KyS: Trình bảng, linh kiện, vai trò dự đoán (MCU, cảm biến, driver), nguồn suy ra, tin cậy Note over KyS: ra: bảng KyS->>KP: Xác nhận/sửa từng dòng (ví dụ, 'U3 là MPU6050 chứ không phải MPU9250') [G-FACT] KP->>TT: Tạo AcquisitionRequest cho hộ chiếu còn thiếu (UC-B07)
A10: UC-B03 | B10: Nhập nguồn cấu trúc chính hãng (SVD / ATDF / EDC / header) | C10: sequenceDiagram autonumber participant KyS as Kỹ sư participant TT as Tác tử participant KP as Knowledge Plane KP->>TT: Sniff nội dung, chọn parser (SVD, derivedFrom, dim, cluster, enum, ATDF, module/instance/b Note over TT: ra: facts[] KP->>TT: Ghi qua cổng ghi duy nhất, hợp nhất theo tier, predicate nhiều giá trị (irq, enum) không g Note over TT: ra: WriteResult KP->>TT: Nếu tệp từ thư mục *-Community hoặc không rõ nguồn hãng → tầng bạc TT->>KyS: Librarian báo, số ngoại vi/thanh ghi/bit-field, cảnh báo parser, mâu thuẫn với nguồn khác Note over KyS: ra: báo cáo KyS->>KP: Nếu có mâu thuẫn hoặc phiên bản mới, quyết định ghim phiên bản (UC-B13)
A11: UC-B04 | B11: Trích xuất tri thức từ PDF (datasheet, reference manual, errata) | C11: sequenceDiagram autonumber participant KyS as Kỹ sư participant TT as Tác tử participant KP as Knowledge Plane KP->>TT: Docling/pdfplumber, bố cục, bảng, tiêu đề, nhận diện chương 'Register map', 'Electrical ch Note over TT: ra: bảng + bbox TT->>KP: Librarian dùng mô hình có schema chuyển từng bảng thành fact {subject, predicate, value, u Note over KP: ra: facts KP->>TT: Hợp nhất trùng lặp, phát hiện mâu thuẫn với nguồn khác, xếp nhóm (thanh ghi, chân, điện, e Note over TT: ra: nhóm KP->>KyS: Cắt ảnh vùng bảng làm bằng chứng, đưa vào hàng đợi G-FACT Note over KyS: ra: ảnh cắt KyS->>KP: Duyệt theo nhóm (UC-B10) [G-FACT]
A12: UC-B05 | B12: Trích xuất từ ảnh (schematic chụp, ảnh board, ảnh màn hình đo) | C12: sequenceDiagram autonumber participant KyS as Kỹ sư participant TT as Tác tử participant KP as Knowledge Plane TT->>KP: Gửi ảnh + schema 'nets[], parts[]' cho mô hình thị giác, nhận bảng đề xuất Note over KP: ra: bảng KP->>TT: Đối chiếu với BoardPassport (nếu có) và hộ chiếu chip (tên chân hợp lệ?) Note over TT: ra: cảnh báo TT->>KyS: Trình bảng với ảnh cắt từng vùng, đánh dấu dòng tin cậy thấp KyS->>KP: Sửa/duyệt [G-FACT]
... A57: UC-K01 | B57: Tác tử tự viết công cụ khi thiếu năng lực | C57: sequenceDiagram autonumber participant KyS as Kỹ sư participant TT as Tác tử participant KP as Knowledge Plane TT->>KP: tool.need, nhận diện nhu cầu, viết ToolSpec (vào/ra/effects/deps/acceptance), tool.search Note over KP: ra: ToolSpec TT->>KP: tool.write, coder sinh tool.py + test, kiểm tĩnh import theo effects Note over KP: ra: code, tests KP->>TT: tool.test trong sandbox, pytest + giám sát hiệu ứng thực tế ⊆ khai báo Note over TT: ra: ToolReport, effects_ok TT->>KP: Thất bại → tool.repair ≤ 3 vòng Note over KP: ra: code' KP->>TT: tool.register, khai báo Capability user.<name> (risk từ effects, tier, undo), nạp nóng reg Note over TT: ra: USER-nn KP->>KyS: tool.run trong chuỗi, policy G-TOOL (TOOL-01…05) → sandbox theo effects → kết quả → ledger [G-TOOL] Note over KyS: ra: result KyS->>TT: Chỉ khi hiệu ứng hệ thống/phần cứng ngoài lab hoặc chưa đủ lịch sử, duyệt/từ chối, xem mã Note over TT: ra: decision TT->>KP: Sau ≥ 3 lần ok, tool.promote đề xuất gói kind=tool → Pack owner duyệt → năng lực chính thứ [T2] Note over KP: ra: proposal

Sheet 11. Bước ↔ năng lực
A1: Mã UC | B1: Bước | C1: Làn | D1: Hành động | E1: Năng lực gọi (khai báo hoặc suy ra) | F1: Màn hình | G1: Cổng / mức
A2: UC-A01 | B2: 1 | C2: N | D2: Ra lệnh bằng ngôn ngữ tự nhiên, ví dụ: 'Tạo dự án robot cân bằng từ thư mục ~/robot-kit, chip chưa rõ' (một câu; có thể kèm kéo thả) | E2: project.create (suy ra) | F2: Tổng quan | G2: Lệnh
A3: UC-A01 | B3: 2 | C3: T | D3: Librarian suy ra tên dự án, mô tả, chip/board (nếu nêu), đường dẫn tài liệu từ câu lệnh; điền mọi tham số mặc định (mức tự chủ A3, mô hình, ngân sách) | E3: project.create (suy ra) | F3: Tổng quan
A4: UC-A01 | B4: 3 | C4: K | D4: Tạo .hkw/ với schema store, tệp mặc định, .gitignore; ghi ledger 'project.init' | E4: — (bước của người / không gọi năng lực) | F4: Tổng quan
A5: UC-A01 | B5: 4 | C5: K | D5: Nếu đã biết chip: pull hộ chiếu lõi từ registry/seed và ghim phiên bản vào constraints.yaml | E5: registry.pull (suy ra) | F5: Tổng quan | G5: UC-G04
A6: UC-A01 | B6: 5 | C6: T | D6: Nếu câu lệnh có tài liệu: tự chuyển sang UC-B01 ngay; nếu không: hỏi đúng một câu 'anh có tài liệu board không?' | E6: chat.parse_intent (suy ra) | F6: Tổng quan
A7: UC-A02 | B7: 1 | C7: T | D7: Lấy mã chip từ câu lệnh nếu người nêu (ví dụ 'dùng STM32F411CE'); nếu không, suy ra từ tài liệu ở UC-B02 | E7: chat.parse_intent (suy ra) | F7: Tổng quan / Hộ chiếu chip
A8: UC-A02 | B8: 2 | C8: K | D8: Tra passport.list; nếu có lõi → ghim; nếu không → tìm registry/seed (UC-B08) | E8: passport.list | F8: Tổng quan / Hộ chiếu chip
A9: UC-A02 | B9: 3 | C9: T | D9: Nếu bỏ trống: Librarian sẽ suy ra chip từ tài liệu (SVD/schematic/ảnh) ở UC-B02 và đề xuất; người xác nhận | E9: extract.svd (suy ra) | F9: Tổng quan / Hộ chiếu chip | G9: G-FACT
A10: UC-A02 | B10: 4 | C10: K | D10: Nạp ISA profile tương ứng (armv7e-m, avr8, rv32…) và toolchain manifest | E10: target.flash (suy ra) | F10: Tổng quan / Hộ chiếu chip
A11: UC-A02 | B11: 5 | C11: K | D11: Ghi ledger; cập nhật thanh trạng thái 'Pin: …' | E11: — (bước của người / không gọi năng lực) | F11: Tổng quan / Hộ chiếu chip
A12: UC-A03 | B12: 1 | C12: K | D12: Đọc toolchain manifest của ISA profile (tên, phiên bản tối thiểu, lệnh kiểm, cách cài theo hệ điều hành) | E12: env.install (suy ra) | F12: Môi trường & báo cáo
A13: UC-A03 | B13: 2 | C13: H | D13: Chạy lệnh kiểm từng công cụ (which/--version); phát hiện probe USB | E13: target.probe_read (suy ra) | F13: Môi trường & báo cáo
A14: UC-A03 | B14: 3 | C14: T | D14: Librarian tổng hợp: bắt buộc thiếu gì, tùy chọn thiếu gì, đề xuất lệnh cài theo hệ điều hành | E14: env.install (suy ra) | F14: Môi trường & báo cáo
A15: UC-A03 | B15: 4 | C15: T | D15: Công cụ mở trong danh sách tin cậy: tự cài (T1); công cụ đóng/có license: hướng dẫn người cài (T3) | E15: env.install (suy ra) | F15: Môi trường & báo cáo | G15: G-OPS
A16: UC-A03 | B16: 5 | C16: H | D16: Cài; kiểm lại phiên bản; tính hash nhị phân | E16: env.install (suy ra) | F16: Môi trường & báo cáo
A17: UC-A03 | B17: 6 | C17: K | D17: Ghi tools.lock; ledger; cập nhật thanh trạng thái Toolchain | E17: — (bước của người / không gọi năng lực) | F17: Môi trường & báo cáo
A18: UC-A04 | B18: 1 | C18: T | D18: Áp cấu hình mặc định (Claude/Gemini theo vai trò, reviewer khác hãng, ngân sách 5 USD/ngày, online); chỉ hỏi khi người ra lệnh đổi ('dùng Gemini cho tất cả', 'ngân sách 2 USD') | E18: code.review (suy ra) | F18: Mô hình & chi phí
A19: UC-A04 | B19: 2 | C19: K | D19: Kiểm quy tắc different_vendor_from(coder); kiểm khóa API theo biến môi trường; kiểm mô hình cục bộ (Ollama) | E19: code.generate_module (suy ra) | F19: Mô hình & chi phí
A20: UC-A04 | B20: 3 | C20: K | D20: Chạy bộ kiểm thử hợp đồng 5 ca trên các adapter khả dụng (không tốn nhiều token) | E20: — (bước của người / không gọi năng lực) | F20: Mô hình & chi phí
A21: UC-A04 | B21: 4 | C21: K | D21: Lưu; ghi ledger; cập nhật thanh trạng thái (offline/online, chi phí) | E21: — (bước của người / không gọi năng lực) | F21: Mô hình & chi phí
A22: UC-A05 | B22: 1 | C22: T | D22: Librarian khảo sát repo: build system, thư mục, định dạng mã, README | E22: code.build (suy ra) | F22: Mã nguồn
A23: UC-A05 | B23: 2 | C23: K | D23: Phân tích tĩnh: tìm địa chỉ/bit hằng số; ánh xạ vào hộ chiếu nếu có → CodeUnit CITES/USES | E23: — (bước của người / không gọi năng lực) | F23: Mã nguồn
A24: UC-A05 | B24: 3 | C24: T | D24: Báo cáo: N hằng số khớp hộ chiếu, M hằng số không nguồn (đề xuất mở UC-B07) | E24: report.progress (suy ra) | F24: Mã nguồn
A25: UC-A05 | B25: 4 | C25: N | D25: Xác nhận CONVENTIONS.md; quyết định có bổ sung hkw:fact vào mã cũ dần hay không | E25: — (bước của người / không gọi năng lực) | F25: Mã nguồn
A26: UC-A06 | B26: 1 | C26: K | D26: Kiểm hash store (phát hiện ghi ngoài cổng); nạp đồ thị từ cache hoặc tái dựng | E26: target.flash (suy ra) | F26: Tổng quan
A27: UC-A06 | B27: 2 | C27: K | D27: Đọc PROGRESS.md, FEATURES.json, gate đang mở, quyền đã hết hạn | E27: policy.permit (suy ra) | F27: Tổng quan
... A29: UC-A06 | B29: 4 | C29: T | D29: Librarian tóm tắt 'lần trước dừng ở đâu, việc tiếp theo là gì' | E29: — (bước của người / không gọi năng lực) | F29: Tổng quan
A30: UC-B01 | B30: 1 | C30: N | D30: Đưa tài liệu: kéo thả zip/thư mục, hoặc nêu đường dẫn trong câu lệnh ('tài liệu ở ~/robot-kit') | E30: archive.unpack (suy ra) | F30: Nhập tài liệu | G30: Lệnh
A31: UC-B01 | B31: 2 | C31: K | D31: Mở nén đệ quy trong sandbox (≤ 5 cấp, ≤ 2 GB, chống zip-slip); tính sha256 từng tệp | E31: archive.unpack (suy ra) | F31: Nhập tài liệu
A32: UC-B01 | B32: 3 | C32: K | D32: Phân loại theo chữ ký nội dung: SVD/ATDF/EDC/header/kicad → vàng; PDF/DOCX/HTML/ảnh → bạc; văn bản tự do/diễn đàn → đồng; khác → bỏ qua | E32: ingest.classify (suy ra) | F32: Nhập tài liệu
A33: UC-B01 | B33: 4 | C33: T | D33: Librarian tóm tắt: tệp nào sinh hộ chiếu ngay, tệp nào cần trích xuất + duyệt, tệp nào chỉ làm ngữ cảnh; phát hiện chip/board từ tên và nội dung | E33: extract.image_schematic (suy ra) | F33: Nhập tài liệu
A34: UC-B01 | B34: 5 | C34: K | D34: Tệp vàng: chạy parser ngay → hộ chiếu (UC-B03/UC-B06). Tệp bạc: tạo AcquisitionRequest CONFIRMED → chờ trích xuất (UC-B04/B05) | E34: — (bước của người / không gọi năng lực) | F34: Nhập tài liệu
A35: UC-B01 | B35: 6 | C35: T | D35: Tự trích xuất mọi tệp bạc ngay (A3); người chỉ xem bảng và có thể loại tệp sau | E35: — (bước của người / không gọi năng lực) | F35: Nhập tài liệu
A36: UC-B01 | B36: 7 | C36: K | D36: Ghi ledger; cập nhật hàng đợi xác nhận | E36: — (bước của người / không gọi năng lực) | F36: Nhập tài liệu
