Workbook

Sheet 0. Hướng dẫn
A1: EIDE-PLN-27 — KẾ HOẠCH PHÁT TRIỂN VÀ BACKLOG THEO MỐC (v1.0)
A2: Đề án tốt nghiệp Thạc sĩ ngành Kỹ thuật Điện tử — PTIT · Học viên: Vũ Trí Công · Người hướng dẫn: TS. Nguyễn Trung Hiếu · 05/09/2026
A3: Sheet 1 Mốc: phạm vi, tiêu chí xong, số việc (công thức). Sheet 2 Backlog: một dòng cho mỗi việc (hạ tầng, năng lực, UI, tài liệu, test) với mốc, ưu tiên, ước lượng, phụ thuộc, ai làm (người/AI), tài liệu tham chiếu, trạng thái. Sheet 3 Truy vết hợp nhất: UR → FR/năng lực → thiết kế → TC → màn hình. Sheet 4 Phân công Người–AI: theo loại việc. Sheet 5 Thống kê (công thức).
A4: Quy ước: ước lượng theo ngày công có AI hỗ trợ (tác tử coder viết phần lớn mã dưới sự duyệt của người); 'AI làm' = tác tử làm trọn, 'AI làm/người duyệt' = AI viết người review, 'Người' = quyết định/thiết kế/kiểm phần cứng.
A5: Cột Trạng thái có danh sách chọn (Chưa · Đang · Xong · Bỏ). Lọc theo Mốc để lấy backlog của sprint.

Sheet 1. Mốc
A1: Mốc | B1: Phạm vi | C1: Tiêu chí xong | D1: Số việc | E1: Ngày ước lượng | F1: Đã xong | G1: Tiến độ
A2: M0 | B2: Khung: schema, store, KG, SVD/ATDF, gateway, CLI — ĐÃ XONG (hkw-core) | C2: 24 test đạt; 640 chip seed; 100/100 truy vấn | D2: =COUNTIF('2. Backlog'!D:D,"M0") | E2: =SUMIF('2. Backlog'!D:D,"M0",'2. Backlog'!F:F) | F2: =COUNTIFS('2. Backlog'!D:D,"M0",'2. Backlog'!K:K,"Xong") | G2: =IF(D2=0,0,F2/D2)
A3: M1 | B3: Lõi tác tử: registry năng lực, chính sách, orchestrator, ngữ cảnh, bộ nhớ, tool.*, extract PDF/ảnh/zip, RAG, plugin chat cơ bản, prompt | C3: Kịch bản Z-01…Z-10 chạy; ≤ 5 bấm với sim; TC M1 đạt | D3: =COUNTIF('2. Backlog'!D:D,"M1") | E3: =SUMIF('2. Backlog'!D:D,"M1",'2. Backlog'!F:F) | F3: =COUNTIFS('2. Backlog'!D:D,"M1",'2. Backlog'!K:K,"Xong") | G3: =IF(D3=0,0,F3/D3)
A4: M2 | B4: Mạch, kiến trúc, mã/merge tự động, lược đồ, tài liệu, dò board, target, sim, benchmark, installer, panel còn lại | C4: Kịch bản chuẩn 17 bước đầu-cuối trên Nucleo + Uno với 2 mô hình; tài liệu SRS/SAD sinh tự động | D4: =COUNTIF('2. Backlog'!D:D,"M2") | E4: =SUMIF('2. Backlog'!D:D,"M2",'2. Backlog'!F:F) | F4: =COUNTIFS('2. Backlog'!D:D,"M2",'2. Backlog'!K:K,"Xong") | G4: =IF(D4=0,0,F4/D4)
A5: M3 | B5: Quan sát: log lớn, probe, debug, sync lược đồ/tài liệu, measure | C5: Kịch bản C log ≥ 1 GB; HardFault chẩn đoán đúng ≥ 80% | D5: =COUNTIF('2. Backlog'!D:D,"M3") | E5: =SUMIF('2. Backlog'!D:D,"M3",'2. Backlog'!F:F) | F5: =COUNTIFS('2. Backlog'!D:D,"M3",'2. Backlog'!K:K,"Xong") | G5: =IF(D5=0,0,F5/D5)
A6: M4 | B6: Registry lớp, template, gói công cụ, ký, publish | C6: ≥ 500 gói hạt giống + 20 kiểm định; tool.promote hoạt động | D6: =COUNTIF('2. Backlog'!D:D,"M4") | E6: =SUMIF('2. Backlog'!D:D,"M4",'2. Backlog'!F:F) | F6: =COUNTIFS('2. Backlog'!D:D,"M4",'2. Backlog'!K:K,"Xong") | G6: =IF(D6=0,0,F6/D6)
A7: M5 | B7: Mở rộng: PIC, chế độ cục bộ, đa người dùng, sigrok, Windows/Linux UI | C7: Theo nhu cầu | D7: =COUNTIF('2. Backlog'!D:D,"M5") | E7: =SUMIF('2. Backlog'!D:D,"M5",'2. Backlog'!F:F) | F7: =COUNTIFS('2. Backlog'!D:D,"M5",'2. Backlog'!K:K,"Xong") | G7: =IF(D7=0,0,F7/D7)

Sheet 2. Backlog
A1: Mã việc | B1: Loại | C1: Việc | D1: Mốc | E1: Ưu tiên | F1: Ước lượng (ngày) | G1: Phụ thuộc | H1: Ai làm | I1: Tài liệu tham chiếu | J1: Năng lực | K1: Trạng thái
A2: WI-001 | B2: Hạ tầng | C2: Khởi tạo kho eide: lõi eide_core/ tách riêng, CLI argparse, không kế thừa hkw-core | D2: M1 | E2: M | F2: 1 | H2: AI làm/người duyệt | I2: DEP-26, CON-28, SAD-03 ADR-16 | K2: Chưa
A3: WI-002 | B3: Hạ tầng | C3: Migration 0002_m1 (bảng policy/runtime) + eide migrate | D3: M1 | E3: M | F3: 1.5 | G3: WI-001 | H3: AI làm/người duyệt | I3: DDD-14 §5 | K3: Chưa
A4: WI-003 | B4: Hạ tầng | C4: Capability Registry + Router (nạp capabilities/*.yaml, invoke, grounding, ledger, undo) | D4: M1 | E4: M | F4: 4 | G4: WI-002 | H4: AI làm/người duyệt | I4: SDD-04 §4.0, CDS-12 | K4: Chưa
A5: WI-004 | B5: Hạ tầng | C5: PolicyGate + rules.yaml + autonomy.yaml + UndoService + decision_log | D5: M1 | E5: M | F5: 4 | G5: WI-003 | H5: AI làm/người duyệt | I5: POL-17 | K5: Chưa
A6: WI-005 | B6: Hạ tầng | C6: Orchestrator (intent, ground, defaults, clarify, chain, runner, report) + chains/*.yaml | D6: M1 | E6: M | F6: 6 | G6: WI-003, WI-004 | H6: AI làm/người duyệt | I6: DPS-09, PRS-16 | K6: Chưa
A7: WI-006 | B7: Hạ tầng | C7: Composer + Compressor (ContextBundle, Graph-RAG 2 bước, ngân sách, cache marks) | D7: M1 | E7: M | F7: 4 | G7: WI-003 | H7: AI làm/người duyệt | I7: CXD-10 | K7: Chưa
A8: WI-007 | B8: Hạ tầng | C8: Memory: WorkingMemory/Session/ErrorLedger/Preference; PROGRESS/FEATURES sinh tự động; resume | D8: M1 | E8: M | F8: 3 | G8: WI-002 | H8: AI làm/người duyệt | I8: MEM-11 | K8: Chưa
A9: WI-008 | B9: Hạ tầng | C9: Ledger chuỗi hash + bộ lọc bí mật + api/errors.json | D9: M1 | E9: M | F9: 1.5 | H9: AI làm/người duyệt | I9: API-15 §6–7, SEC-25 | K9: Chưa
A10: WI-009 | B10: Hạ tầng | C10: Sandbox (tiến trình con, giới hạn, giám sát hiệu ứng, audit hook) | D10: M1 | E10: M | F10: 3 | H10: AI làm/người duyệt | I10: SEC-25 §2 | K10: Chưa
A11: WI-010 | B11: Hạ tầng | C11: JSON-RPC server + OpenRPC + REST nội bộ + CLI eide "<lệnh>" | D11: M1 | E11: M | F11: 4 | G11: WI-003, WI-005 | H11: AI làm/người duyệt | I11: API-15 | K11: Chưa
A12: WI-011 | B12: Hạ tầng | C12: MCP server sinh tool từ registry (caps_*, chat_command, 12 tool nhanh) | D12: M1 | E12: M | F12: 2 | G12: WI-003 | H12: AI làm/người duyệt | I12: API-15 §3 | K12: Chưa
A13: WI-012 | B13: Hạ tầng | C13: RagIndex (chunk, embedding qua Gateway, FTS5, gắn IRI, truy hồi lai) | D13: M1 | E13: M | F13: 3 | G13: WI-002 | H13: AI làm/người duyệt | I13: KAD-07 §6.9, CDS view.rag_index | K13: Chưa
A14: WI-013 | B14: Hạ tầng | C14: Prompt 9 vai trò + roles/models.yaml + 50 câu lệnh + test L2b | D14: M1 | E14: M | F14: 2 | G14: WI-005 | H14: AI làm/người duyệt | I14: PRS-16 | K14: Chưa
A15: WI-014 | B15: Hạ tầng | C15: Migration 0004_m2 (module, hw_map, adr, doc_artifact, discovery, measurement) | D15: M2 | E15: M | F15: 1 | G15: WI-002 | H15: AI làm/người duyệt | I15: DDD-14 | K15: Chưa
A16: WI-015 | B16: Hạ tầng | C16: Bộ render lược đồ (mmdc/plantuml/dot/d2/wavedrom) trong sandbox + lint | D16: M2 | E16: M | F16: 2 | G16: WI-009 | H16: AI làm/người duyệt | I16: CDS diagram.render | K16: Chưa
A17: WI-016 | B17: Hạ tầng | C17: Mẫu docx Python (port eaa_doc) + style_check | D17: M2 | E17: M | F17: 2 | H17: AI làm/người duyệt | I17: CDS doc.generate | K17: Chưa
A18: WI-017 | B18: Hạ tầng | C18: Adapter target theo ISA (probe-rs, openocd, avrdude, esptool) + serial daemon | D18: M2 | E18: M | F18: 4 | G18: WI-009 | H18: AI làm/người duyệt | I18: TGT-19 | K18: Chưa
A19: WI-018 | B19: Hạ tầng | C19: Discovery (ports/probe/chip_id/link_speed/auto_setup) + bảng VID/PID + id_tables | D19: M2 | E19: M | F19: 4 | G19: WI-017 | H19: AI làm/người duyệt | I19: TGT-19 §4–6 | K19: Chưa
A20: WI-019 | B20: Hạ tầng | C20: Sim: Renode .repl từ hộ chiếu + mock BME280/MPU6050/A4988 + plant robot + kịch bản | D20: M2 | E20: M | F20: 6 | G20: WI-017 | H20: AI làm/người duyệt | I20: SIM-20 | K20: Chưa
A21: WI-020 | B21: Hạ tầng | C21: ToolForge: tool.need/search/write/test/run/register/repair (+ G-TOOL) | D21: M1 | E21: M | F21: 4 | G21: WI-003, WI-004, WI-009 | H21: AI làm/người duyệt | I21: CDS-12 tập 3 tool.* | K21: Chưa
A22: WI-021 | B22: Hạ tầng | C22: Plugin GEditor: RpcClient sinh từ openrpc + ChatPanel + AutonomyBar + QueuePanel | D22: M1 | E22: M | F22: 6 | G22: WI-010 | H22: AI làm/người duyệt (Swift) | I22: GPI-23, UXD-13 | K22: Chưa
A23: WI-022 | B23: Hạ tầng | C23: Plugin GEditor: KnowledgeMap/RagAsk/ReqArch/DiagramView/Doc/Discovery/ToolForge panels | D23: M2 | E23: M | F23: 8 | G23: WI-021 | H23: AI làm/người duyệt (Swift) | I23: UXD-13 | K23: Chưa
A24: WI-023 | B24: Hạ tầng | C24: Plugin GEditor: LogAssist/Debug/Sim panels + providers | D24: M3 | E24: M | F24: 5 | G24: WI-022 | H24: AI làm/người duyệt (Swift) | I24: UXD-13, GPI-23 | K24: Chưa
A25: WI-024 | B25: Hạ tầng | C25: Registry lớp: index.json, pack/sign/publish/pull, template K5′ balancing-robot | D25: M4 | E25: M | F25: 4 | G25: WI-003 | H25: AI làm/người duyệt | I25: PKG-22 | K25: Chưa
A26: WI-025 | B26: Hạ tầng | C26: Installer + daemon launchd/systemd + CI (test/contract/dialog/hil/release/docs) | D26: M2 | E26: M | F26: 3 | G26: WI-010 | H26: AI làm/người duyệt | I26: DEP-26 | K26: Chưa
A27: WI-026 | B27: Hạ tầng | C27: Bộ benchmark 20 tác vụ + firmware kiểm định + runner board | D27: M2 | E27: M | F27: 4 | G27: WI-017 | H27: AI làm/người duyệt | I27: BEN-21 | K27: Chưa
A28: WI-027 | B28: Năng lực | C28: PROJECT-03 project.list — Liệt kê dự án trong workspace với ngày, board, tiến độ | D28: M1 | E28: M | F28: 0.5 | G28: WI-003 | H28: AI làm | I28: CDS-12 tập 3 | J28: project.list | K28: Chưa
A29: WI-028 | B29: Năng lực | C29: PROJECT-04 project.clone — Nhân bản dự án thành dự án mới (giữ tri thức, bỏ ledger) | D29: M2 | E29: M | F29: 1 | G29: WI-003 | H29: AI làm | I29: CDS-12 tập 3 | J29: project.clone | K29: Chưa
A30: WI-029 | B30: Năng lực | C30: PROJECT-05 project.archive — Lưu trữ/đóng dự án (không xóa) | D30: M2 | E30: M | F30: 1 | G30: WI-003 | H30: AI làm | I30: CDS-12 tập 3 | J30: project.archive | K30: Chưa
A31: WI-030 | B31: Năng lực | C31: PROJECT-06 project.set_target — Đặt/suy ra ISA, chip, board; ghim phiên bản hộ chiếu | D31: M0 | E31: M | F31: 1 | G31: WI-003 | H31: AI làm | I31: CDS-12 tập 3 | J31: project.set_target | K31: Chưa
A32: WI-031 | B32: Năng lực | C32: PROJECT-07 project.rollback — Về known-good gần nhất hoặc tag chỉ định | D32: M2 | E32: M | F32: 1 | G32: WI-003 | H32: AI làm | I32: CDS-12 tập 3 | J32: project.rollback | K32: Chưa
A33: WI-032 | B33: Năng lực | C33: PROJECT-08 project.status — Tổng hợp tiến độ, feature, gate mở, chi phí | D33: M1 | E33: M | F33: 0.5 | G33: WI-003 | H33: AI làm | I33: CDS-12 tập 3 | J33: project.status | K33: Chưa
A34: WI-033 | B34: Năng lực | C34: PROJECT-09 project.preferences — Ghi/đọc tùy chọn đã học từ câu trả lời của kỹ sư | D34: M1 | E34: M | F34: 0.75 | G34: WI-003 | H34: AI làm | I34: CDS-12 tập 3 | J34: project.preferences | K34: Chưa
A35: WI-034 | B35: Năng lực | C35: MEMORY-01 memory.compose — Ghép ngữ cảnh 7 lớp K1–K7 theo vai trò và tác vụ; kiểm ngân sách token | D35: M1 | E35: M | F35: 0.5 | G35: WI-003 | H35: AI làm | I35: CDS-12 tập 6 | J35: memory.compose | K35: Chưa
A36: WI-035 | B36: Năng lực | C36: MEMORY-02 memory.compress — Nén ngữ cảnh: tóm tắt lịch sử, lọc log theo mẫu, rút gọn fact | D36: M1 | E36: M | F36: 0.5 | G36: WI-003 | H36: AI làm | I36: CDS-12 tập 6 | J36: memory.compress | K36: Chưa
A37: WI-036 | B37: Năng lực | C37: MEMORY-03 memory.retrieve — Truy hồi Graph-RAG: lan tỏa 2 bước từ subject rồi lấy văn bản | D37: M2 | E37: M | F37: 0.5 | G37: WI-003 | H37: AI làm | I37: CDS-12 tập 6 | J37: memory.retrieve | K37: Chưa
A38: WI-037 | B38: Năng lực | C38: MEMORY-04 memory.progress — Ghi/đọc PROGRESS.md, FEATURES.json (harness dài hạn) | D38: M1 | E38: M | F38: 0.75 | G38: WI-003 | H38: AI làm | I38: CDS-12 tập 6 | J38: memory.progress | K38: Chưa
A39: WI-038 | B39: Năng lực | C39: MEMORY-06 memory.error_ledger — Sổ lỗi: ghi lỗi ảo giác/từ chối; đưa vào prompt phủ định | D39: M2 | E39: M | F39: 0.75 | G39: WI-003 | H39: AI làm | I39: CDS-12 tập 6 | J39: memory.error_ledger | K39: Chưa
... A246: WI-245 | B246: Năng lực | C246: TOOL-10 tool.deprecate — Vô hiệu hóa công cụ lỗi/không dùng; giữ lịch sử; thay thế bằng năng lự | D246: M2 | E246: M | F246: 0.75 | G246: WI-003 | H246: AI làm | I246: CDS-12 tập 3 | J246: tool.deprecate | K246: Chưa
...

Sheet 3. Truy vết hợp nhất
A1: Nhóm UR | B1: Nhóm năng lực | C1: FR (năng lực) | D1: Thiết kế | E1: Test case | F1: Màn hình
A2: UR-TT-* | B2: archive | C2: FR-ARCHIVE-01…07 | D2: CDS-12 tập 2; SDD-04 §4 | E2: TC-11, TC-SE-02 | F2: Ingest
A3: UR-TT-* | B3: search | C3: FR-SEARCH-01…09 | D3: CDS-12 tập 2; SDD-04 §4 | E3: TC-07, S01…S07 | F3: Ingest
A4: UR-TT-* | B4: extract | C4: FR-EXTRACT-01…21 | D4: CDS-12 tập 2; SDD-04 §4 | E4: TC-09, TC-10, TC-12, TC-22 | F4: Ingest/Passport
A5: UR-TT-* | B5: passport | C5: FR-PASSPORT-01…08 | D5: CDS-12 tập 2; SDD-04 §4 | E5: TC-15, TC-16, TC-18 | F5: Passport
A6: UR-TT-* | B6: kg | C6: FR-KG-01…09 | D6: CDS-12 tập 2; SDD-04 §4 | E6: TC-13, TC-17, S09…S17 | F6: RagAsk/ReviewQueue
A7: UR-MC-* | B7: board | C7: FR-BOARD-01…05 | D7: CDS-12 tập 2; SDD-04 §4 | E7: TC-20, TC-21 | F7: Board
A8: UR-MA-* | B8: plan | C8: FR-PLAN-01…07 | D8: CDS-12 tập 1; SDD-04 §4 | E8: TC-26, S18…S22 | F8: PlanDiff
A9: UR-MA-* | B9: code | C9: FR-CODE-01…16 | D9: CDS-12 tập 3; SDD-04 §4 | E9: TC-04, TC-31, S23…S28 | F9: Code/PlanDiff
A10: UR-MA-* | B10: memory | C10: FR-MEMORY-01…08 | D10: CDS-12 tập 6; SDD-04 §4 | E10: TC-MM-01…09, TC-CX-01…08 | F10: Chat
A11: UR-XM-* | B11: sim | C11: FR-SIM-01…07 | D11: CDS-12 tập 4; SDD-04 §4 | E11: TC-34, TC-SM-01…06 | F11: Sim
A12: UR-XM-* | B12: target | C12: FR-TARGET-01…09 | D12: CDS-12 tập 4; SDD-04 §4 | E12: TC-32, TC-33, TC-36, TC-TG-05 | F12: Discovery/Debug
... A37: UR-DT-* | B37: target | C37: FR-TARGET-01…09 | D37: CDS-12 tập 4; SDD-04 §4 | E37: TC-32, TC-33, TC-36, TC-TG-05 | F37: Discovery/Debug

Sheet 4. Phân công Người–AI
A1: Loại việc | B1: Ai làm | C1: Ghi chú
A2: Thiết kế và quyết định kiến trúc | B2: Người (chủ sản phẩm) + AI đề xuất | C2: ADR, danh sách trắng, ngưỡng chính sách, mức tự chủ
A3: Viết mã năng lực T1 (R0/R1) | B3: AI làm (coder) — người review theo mẫu | C3: Test hợp đồng sinh tự động; reviewer AI khác hãng
A4: Viết mã hạ tầng (Router, PolicyGate, Orchestrator, Sandbox) | B4: AI viết / người duyệt kỹ | C4: Bất biến an toàn phải có test cưỡng chế
A5: Plugin Swift | B5: AI viết / người duyệt + chạy trên GEditor thật | C5: Mã RPC sinh từ openrpc
A6: Prompt và skill | B6: AI dự thảo / người duyệt + benchmark | C6: PRS-16 §8
A7: Kiểm phần cứng (L3), đo tham số, board lab | B7: Người | C7: Runner có board; ký danh sách trắng
A8: Tài liệu | B8: AI sinh từ mô hình / người duyệt | C8: docs job trong CI
A9: Pháp lý license registry công khai | B9: Người | C9: PKG-22

Sheet 5. Thống kê
A1: THỐNG KÊ BACKLOG (công thức)
A3: Tổng việc | B3: =COUNTA('2. Backlog'!A:A)-1
A4: Tổng ngày ước lượng | B4: =SUM('2. Backlog'!F:F)
A5: Đã xong | B5: =COUNTIF('2. Backlog'!K:K,"Xong")
A6: Tiến độ | B6: =B5/B3
A8: Theo loại
A9: Hạ tầng | B9: =COUNTIF('2. Backlog'!B:B,"Hạ tầng") | C9: =SUMIF('2. Backlog'!B:B,"Hạ tầng",'2. Backlog'!F:F)
A10: Năng lực | B10: =COUNTIF('2. Backlog'!B:B,"Năng lực") | C10: =SUMIF('2. Backlog'!B:B,"Năng lực",'2. Backlog'!F:F)
A11: Tài liệu | B11: =COUNTIF('2. Backlog'!B:B,"Tài liệu") | C11: =SUMIF('2. Backlog'!B:B,"Tài liệu",'2. Backlog'!F:F)
A12: Kiểm thử | B12: =COUNTIF('2. Backlog'!B:B,"Kiểm thử") | C12: =SUMIF('2. Backlog'!B:B,"Kiểm thử",'2. Backlog'!F:F)
A13: Người | B13: =COUNTIF('2. Backlog'!B:B,"Người") | C13: =SUMIF('2. Backlog'!B:B,"Người",'2. Backlog'!F:F)
A15: Theo ai làm
A16: AI làm | B16: =COUNTIF('2. Backlog'!H:H,"AI làm") | C16: =SUMIF('2. Backlog'!H:H,"AI làm",'2. Backlog'!F:F)
A17: AI làm/người duyệt | B17: =COUNTIF('2. Backlog'!H:H,"AI làm/người duyệt") | C17: =SUMIF('2. Backlog'!H:H,"AI làm/người duyệt",'2. Backlog'!F:F)
A18: AI làm/người duyệt (Swift) | B18: =COUNTIF('2. Backlog'!H:H,"AI làm/người duyệt (Swift)") | C18: =SUMIF('2. Backlog'!H:H,"AI làm/người duyệt (Swift)",'2. Backlog'!F:F)
A19: Người | B19: =COUNTIF('2. Backlog'!H:H,"Người") | C19: =SUMIF('2. Backlog'!H:H,"Người",'2. Backlog'!F:F)
