Workbook

Sheet 0. Hướng dẫn
A1: EIDE — DANH MỤC NĂNG LỰC ĐẦY ĐỦ (CAPABILITY CATALOG)
A2: Đề án tốt nghiệp Thạc sĩ ngành Kỹ thuật Điện tử — Học viện Công nghệ Bưu chính Viễn thông (PTIT) · Học viên: Vũ Trí Công · Người hướng dẫn: TS. Nguyễn Trung Hiếu
A3: Mọi chức năng phần mềm là một năng lực có hợp đồng; tác tử hiểu lệnh → đối chiếu trạng thái → lập chuỗi → gọi năng lực theo chính sách tự chủ (EIDE-APD-08, DPS-09). 05/09/2026 · Vũ Trí Công (hỗ trợ: Claude)
A5: Cột
A6: Mã / Nhóm: không gian tên của năng lực (project, memory, archive, search, extract, passport, kg, board, env, plan, code, sim, target, debug, measure, bench, registry, report, policy, chat, req, arch, diagram, doc, view, discover, tool).
A7: Lớp rủi ro R0 đọc · R1 ghi tri thức · R2 ghi mã · R3 phần cứng lab · R4 không hoàn tác/vật lý (APD §3).
A8: Mức: T1 AI làm trọn · T1* tự làm khi chính sách đủ bằng chứng, nếu không hỏi · T2 AI làm — người duyệt · T3 người làm.
A9: Grounding: điều tác tử phải đối chiếu trước khi gọi. Hỏi kỹ sư khi: điều kiện chuyển sang hỏi. Trạng thái M0: đã có trong hkw-core hay chưa.
A10: Sheet 2 thống kê bằng công thức theo nhóm/mức/lớp rủi ro/trạng thái. Sheet 3 xếp năng lực theo vòng đời kỹ nghệ (yêu cầu → kiến trúc → thiết kế → mã → kiểm thử → tài liệu).
A11: Bổ sung 05/09 (v1.2): nhóm tool (tác tử tự viết công cụ Python và chạy — năng lực gốc sinh năng lực khác); (v1.1): nhóm req (phân tích yêu cầu), view (bản đồ tri thức, RAG), discover (dò board, probe, tốc độ kết nối), arch (thiết kế kiến trúc), diagram (vẽ lược đồ bằng ngôn ngữ GEditor hỗ trợ: Mermaid, PlantUML, Graphviz/DOT, D2, WaveDrom, SVG), doc (viết tài liệu theo chuẩn bộ EAA/EIDE).

Sheet 1. Danh mục năng lực
A1: Mã | B1: Nhóm | C1: Năng lực | D1: Mô tả | E1: Tham số vào | F1: Kết quả ra | G1: Lớp rủi ro | H1: Mức | I1: Grounding / tiền điều kiện | J1: Hỏi kỹ sư khi | K1: UC / tham chiếu | L1: Mốc | M1: Trạng thái M0
A2: PROJECT-01 | B2: project | C2: project.create | D2: Tạo dự án từ câu lệnh; suy ra tên/mô tả/đường dẫn/chip; áp mặc định | E2: text, docs_path?, chip?, autonomy? | F2: project_id, .hkw/ | G2: R2 | H2: T1 | I2: Kiểm trùng tên/gần giống; mẫu tham chiếu | J2: Trùng tên đúng; ghi đè | K2: UC-A01 | L2: M0 | M2: có (init)
A3: PROJECT-02 | B3: project | C3: project.open | D3: Mở dự án đã có; kiểm hash store; tái dựng đồ thị | E3: project_id|path | F3: state summary | G3: R0 | H3: T1 | I3: Hash store hợp lệ | J3: Hash lệch (ghi ngoài cổng) | K3: UC-A06 | L3: M0 | M3: có
A4: PROJECT-03 | B4: project | C4: project.list | D4: Liệt kê dự án trong workspace với ngày, board, tiến độ | E4: — | F4: projects[] | G4: R0 | H4: T1 | I4: — | J4: — | K4: Z-02 | L4: M1 | M4: chưa
A5: PROJECT-04 | B5: project | C5: project.clone | D5: Nhân bản dự án thành dự án mới (giữ tri thức, bỏ ledger) | E5: src, new_name | F5: project_id | G5: R2 | H5: T1 | I5: — | J5: — | K5: Z-02 | L5: M2 | M5: chưa
A6: PROJECT-05 | B6: project | C6: project.archive | D6: Lưu trữ/đóng dự án (không xóa) | E6: project_id | F6: — | G6: R2 | H6: T1 | I6: — | J6: Xóa thật sự (R4) | K6: Z-08 | L6: M2 | M6: chưa
A7: PROJECT-06 | B7: project | C7: project.set_target | D7: Đặt/suy ra ISA, chip, board; ghim phiên bản hộ chiếu | E7: chip?, isa?, board? | F7: pins | G7: R2 | H7: T1 | I7: Hộ chiếu có trong store/registry | J7: Tài liệu nêu >1 chip | K7: UC-A02 | L7: M0 | M7: một phần
A8: PROJECT-07 | B8: project | C8: project.rollback | D8: Về known-good gần nhất hoặc tag chỉ định | E8: tag? | F8: state | G8: R2 | H8: T1 | I8: Có tag | J8: — | K8: UC-D06 | L8: M2 | M8: chưa
A9: PROJECT-08 | B9: project | C9: project.status | D9: Tổng hợp tiến độ, feature, gate mở, chi phí | E9: — | F9: report | G9: R0 | H9: T1 | I9: — | J9: — | K9: UC-A06 | L9: M1 | M9: một phần
A10: PROJECT-09 | B10: project | C10: project.preferences | D10: Ghi/đọc tùy chọn đã học từ câu trả lời của kỹ sư | E10: key, value? | F10: prefs | G10: R1 | H10: T1 | I10: — | J10: — | K10: D8 | L10: M1 | M10: chưa
A11: MEMORY-01 | B11: memory | C11: memory.compose | D11: Ghép ngữ cảnh 7 lớp K1–K7 theo vai trò và tác vụ; kiểm ngân sách token | E11: role, task | F11: context ≤ budget | G11: R0 | H11: T1 | I11: — | J11: — | K11: FR-AGT-02 | L11: M1 | M11: thiết kế
A12: MEMORY-02 | B12: memory | C12: memory.compress | D12: Nén ngữ cảnh: tóm tắt lịch sử, lọc log theo mẫu, rút gọn fact | E12: context | F12: context' | G12: R0 | H12: T1 | I12: — | J12: — | K12: FR-AGT-02 | L12: M1 | M12: chưa
... A239: TOOL-10 | B239: tool | C239: tool.deprecate | D239: Vô hiệu hóa công cụ lỗi/không dùng; giữ lịch sử; thay thế bằng năng lực chính thức khi có | E239: tool_id, reason | F239: — | G239: R1 | H239: T1 | I239: — | J239: — | K239: — | L239: M2 | M239: chưa

Sheet 2. Thống kê
A1: THỐNG KÊ (công thức)
A2: Tổng năng lực | B2: =COUNTA('1. Danh mục năng lực'!A2:A239) -> 238
A3: Đã có trong M0 (chứa 'có') | B3: =COUNTIF('1. Danh mục năng lực'!M2:M239,"*có*") -> 19
A5: Theo mức | B5: Số | C5: Tỷ lệ
A6: T1 | B6: =COUNTIF('1. Danh mục năng lực'!H2:H239,"T1") -> 205 | C6: =B6/$B$2 -> 0.86134454
A7: T1* | B7: =COUNTIF('1. Danh mục năng lực'!H2:H239,"T1~*") -> 15 | C7: =B7/$B$2 -> 0.06302521
A8: T2 | B8: =COUNTIF('1. Danh mục năng lực'!H2:H239,"T2") -> 15 | C8: =B8/$B$2 -> 0.06302521
A9: T3 | B9: =COUNTIF('1. Danh mục năng lực'!H2:H239,"T3") -> 3 | C9: =B9/$B$2 -> 0.012605042
A11: Theo lớp rủi ro | B11: Số
A12: R0 | B12: =COUNTIF('1. Danh mục năng lực'!G2:G239,"R0*") -> 140
A13: R1 | B13: =COUNTIF('1. Danh mục năng lực'!G2:G239,"R1*") -> 70
A14: R2 | B14: =COUNTIF('1. Danh mục năng lực'!G2:G239,"R2*") -> 20
A15: R3 | B15: =COUNTIF('1. Danh mục năng lực'!G2:G239,"R3*") -> 6
A16: R4 | B16: =COUNTIF('1. Danh mục năng lực'!G2:G239,"R4*") -> 2
A18: Theo nhóm | B18: Số | C18: T1 | D18: T2 | E18: T3
A19: arch | B19: =COUNTIF('1. Danh mục năng lực'!B2:B239,"arch") -> 11 | C19: =COUNTIFS('1. Danh mục năng lực'!B2:B239,"arch",'1. Danh mục năng lực'!H2:H239,"T1~*")+COUNTIFS('1. Danh mục năng lực'!B2:B239,"arch",'1. Danh mục năng lực'!H2:H239,"T1") -> 11 | D19: =COUNTIFS('1. Danh mục năng lực'!B2:B239,"arch",'1. Danh mục năng lực'!H2:H239,"T2") -> 0 | E19: =COUNTIFS('1. Danh mục năng lực'!B2:B239,"arch",'1. Danh mục năng lực'!H2:H239,"T3") -> 0
A20: archive | B20: =COUNTIF('1. Danh mục năng lực'!B2:B239,"archive") -> 7 | C20: =COUNTIFS('1. Danh mục năng lực'!B2:B239,"archive",'1. Danh mục năng lực'!H2:H239,"T1~*")+COUNTIFS('1. Danh mục năng lực'!B2:B239,"archive",'1. Danh mục năng lực'!H2:H239,"T1") -> 7 | D20: =COUNTIFS('1. Danh mục năng lực'!B2:B239,"archive",'1. Danh mục năng lực'!H2:H239,"T2") -> 0 | E20: =COUNTIFS('1. Danh mục năng lực'!B2:B239,"archive",'1. Danh mục năng lực'!H2:H239,"T3") -> 0
A21: bench | B21: =COUNTIF('1. Danh mục năng lực'!B2:B239,"bench") -> 3 | C21: =COUNTIFS('1. Danh mục năng lực'!B2:B239,"bench",'1. Danh mục năng lực'!H2:H239,"T1~*")+COUNTIFS('1. Danh mục năng lực'!B2:B239,"bench",'1. Danh mục năng lực'!H2:H239,"T1") -> 2 | D21: =COUNTIFS('1. Danh mục năng lực'!B2:B239,"bench",'1. Danh mục năng lực'!H2:H239,"T2") -> 1 | E21: =COUNTIFS('1. Danh mục năng lực'!B2:B239,"bench",'1. Danh mục năng lực'!H2:H239,"T3") -> 0
A22: board | B22: =COUNTIF('1. Danh mục năng lực'!B2:B239,"board") -> 5 | C22: =COUNTIFS('1. Danh mục năng lực'!B2:B239,"board",'1. Danh mục năng lực'!H2:H239,"T1~*")+COUNTIFS('1. Danh mục năng lực'!B2:B239,"board",'1. Danh mục năng lực'!H2:H239,"T1") -> 4 | D22: =COUNTIFS('1. Danh mục năng lực'!B2:B239,"board",'1. Danh mục năng lực'!H2:H239,"T2") -> 1 | E22: =COUNTIFS('1. Danh mục năng lực'!B2:B239,"board",'1. Danh mục năng lực'!H2:H239,"T3") -> 0
A23: chat | B23: =COUNTIF('1. Danh mục năng lực'!B2:B239,"chat") -> 8 | C23: =COUNTIFS('1. Danh mục năng lực'!B2:B239,"chat",'1. Danh mục năng lực'!H2:H239,"T1~*")+COUNTIFS('1. Danh mục năng lực'!B2:B239,"chat",'1. Danh mục năng lực'!H2:H239,"T1") -> 7 | D23: =COUNTIFS('1. Danh mục năng lực'!B2:B239,"chat",'1. Danh mục năng lực'!H2:H239,"T2") -> 1 | E23: =COUNTIFS('1. Danh mục năng lực'!B2:B239,"chat",'1. Danh mục năng lực'!H2:H239,"T3") -> 0
A24: code | B24: =COUNTIF('1. Danh mục năng lực'!B2:B239,"code") -> 16 | C24: =COUNTIFS('1. Danh mục năng lực'!B2:B239,"code",'1. Danh mục năng lực'!H2:H239,"T1~*")+COUNTIFS('1. Danh mục năng lực'!B2:B239,"code",'1. Danh mục năng lực'!H2:H239,"T1") -> 16 | D24: =COUNTIFS('1. Danh mục năng lực'!B2:B239,"code",'1. Danh mục năng lực'!H2:H239,"T2") -> 0 | E24: =COUNTIFS('1. Danh mục năng lực'!B2:B239,"code",'1. Danh mục năng lực'!H2:H239,"T3") -> 0
A25: debug | B25: =COUNTIF('1. Danh mục năng lực'!B2:B239,"debug") -> 6 | C25: =COUNTIFS('1. Danh mục năng lực'!B2:B239,"debug",'1. Danh mục năng lực'!H2:H239,"T1~*")+COUNTIFS('1. Danh mục năng lực'!B2:B239,"debug",'1. Danh mục năng lực'!H2:H239,"T1") -> 6 | D25: =COUNTIFS('1. Danh mục năng lực'!B2:B239,"debug",'1. Danh mục năng lực'!H2:H239,"T2") -> 0 | E25: =COUNTIFS('1. Danh mục năng lực'!B2:B239,"debug",'1. Danh mục năng lực'!H2:H239,"T3") -> 0
A26: diagram | B26: =COUNTIF('1. Danh mục năng lực'!B2:B239,"diagram") -> 14 | C26: =COUNTIFS('1. Danh mục năng lực'!B2:B239,"diagram",'1. Danh mục năng lực'!H2:H239,"T1~*")+COUNTIFS('1. Danh mục năng lực'!B2:B239,"diagram",'1. Danh mục năng lực'!H2:H239,"T1") -> 14 | D26: =COUNTIFS('1. Danh mục năng lực'!B2:B239,"diagram",'1. Danh mục năng lực'!H2:H239,"T2") -> 0 | E26: =COUNTIFS('1. Danh mục năng lực'!B2:B239,"diagram",'1. Danh mục năng lực'!H2:H239,"T3") -> 0
A27: discover | B27: =COUNTIF('1. Danh mục năng lực'!B2:B239,"discover") -> 12 | C27: =COUNTIFS('1. Danh mục năng lực'!B2:B239,"discover",'1. Danh mục năng lực'!H2:H239,"T1~*")+COUNTIFS('1. Danh mục năng lực'!B2:B239,"discover",'1. Danh mục năng lực'!H2:H239,"T1") -> 12 | D27: =COUNTIFS('1. Danh mục năng lực'!B2:B239,"discover",'1. Danh mục năng lực'!H2:H239,"T2") -> 0 | E27: =COUNTIFS('1. Danh mục năng lực'!B2:B239,"discover",'1. Danh mục năng lực'!H2:H239,"T3") -> 0
A28: doc | B28: =COUNTIF('1. Danh mục năng lực'!B2:B239,"doc") -> 12 | C28: =COUNTIFS('1. Danh mục năng lực'!B2:B239,"doc",'1. Danh mục năng lực'!H2:H239,"T1~*")+COUNTIFS('1. Danh mục năng lực'!B2:B239,"doc",'1. Danh mục năng lực'!H2:H239,"T1") -> 12 | D28: =COUNTIFS('1. Danh mục năng lực'!B2:B239,"doc",'1. Danh mục năng lực'!H2:H239,"T2") -> 0 | E28: =COUNTIFS('1. Danh mục năng lực'!B2:B239,"doc",'1. Danh mục năng lực'!H2:H239,"T3") -> 0
A29: env | B29: =COUNTIF('1. Danh mục năng lực'!B2:B239,"env") -> 7 | C29: =COUNTIFS('1. Danh mục năng lực'!B2:B239,"env",'1. Danh mục năng lực'!H2:H239,"T1~*")+COUNTIFS('1. Danh mục năng lực'!B2:B239,"env",'1. Danh mục năng lực'!H2:H239,"T1") -> 6 | D29: =COUNTIFS('1. Danh mục năng lực'!B2:B239,"env",'1. Danh mục năng lực'!H2:H239,"T2") -> 0 | E29: =COUNTIFS('1. Danh mục năng lực'!B2:B239,"env",'1. Danh mục năng lực'!H2:H239,"T3") -> 1
A30: extract | B30: =COUNTIF('1. Danh mục năng lực'!B2:B239,"extract") -> 21 | C30: =COUNTIFS('1. Danh mục năng lực'!B2:B239,"extract",'1. Danh mục năng lực'!H2:H239,"T1~*")+COUNTIFS('1. Danh mục năng lực'!B2:B239,"extract",'1. Danh mục năng lực'!H2:H239,"T1") -> 16 | D30: =COUNTIFS('1. Danh mục năng lực'!B2:B239,"extract",'1. Danh mục năng lực'!H2:H239,"T2") -> 5 | E30: =COUNTIFS('1. Danh mục năng lực'!B2:B239,"extract",'1. Danh mục năng lực'!H2:H239,"T3") -> 0
A31: kg | B31: =COUNTIF('1. Danh mục năng lực'!B2:B239,"kg") -> 9 | C31: =COUNTIFS('1. Danh mục năng lực'!B2:B239,"kg",'1. Danh mục năng lực'!H2:H239,"T1~*")+COUNTIFS('1. Danh mục năng lực'!B2:B239,"kg",'1. Danh mục năng lực'!H2:H239,"T1") -> 8 | D31: =COUNTIFS('1. Danh mục năng lực'!B2:B239,"kg",'1. Danh mục năng lực'!H2:H239,"T2") -> 1 | E31: =COUNTIFS('1. Danh mục năng lực'!B2:B239,"kg",'1. Danh mục năng lực'!H2:H239,"T3") -> 0
A32: measure | B32: =COUNTIF('1. Danh mục năng lực'!B2:B239,"measure") -> 3 | C32: =COUNTIFS('1. Danh mục năng lực'!B2:B239,"measure",'1. Danh mục năng lực'!H2:H239,"T1~*")+COUNTIFS('1. Danh mục năng lực'!B2:B239,"measure",'1. Danh mục năng lực'!H2:H239,"T1") -> 3 | D32: =COUNTIFS('1. Danh mục năng lực'!B2:B239,"measure",'1. Danh mục năng lực'!H2:H239,"T2") -> 0 | E32: =COUNTIFS('1. Danh mục năng lực'!B2:B239,"measure",'1. Danh mục năng lực'!H2:H239,"T3") -> 0
A33: memory | B33: =COUNTIF('1. Danh mục năng lực'!B2:B239,"memory") -> 8 | C33: =COUNTIFS('1. Danh mục năng lực'!B2:B239,"memory",'1. Danh mục năng lực'!H2:H239,"T1~*")+COUNTIFS('1. Danh mục năng lực'!B2:B239,"memory",'1. Danh mục năng lực'!H2:H239,"T1") -> 8 | D33: =COUNTIFS('1. Danh mục năng lực'!B2:B239,"memory",'1. Danh mục năng lực'!H2:H239,"T2") -> 0 | E33: =COUNTIFS('1. Danh mục năng lực'!B2:B239,"memory",'1. Danh mục năng lực'!H2:H239,"T3") -> 0
A34: passport | B34: =COUNTIF('1. Danh mục năng lực'!B2:B239,"passport") -> 8 | C34: =COUNTIFS('1. Danh mục năng lực'!B2:B239,"passport",'1. Danh mục năng lực'!H2:H239,"T1~*")+COUNTIFS('1. Danh mục năng lực'!B2:B239,"passport",'1. Danh mục năng lực'!H2:H239,"T1") -> 7 | D34: =COUNTIFS('1. Danh mục năng lực'!B2:B239,"passport",'1. Danh mục năng lực'!H2:H239,"T2") -> 1 | E34: =COUNTIFS('1. Danh mục năng lực'!B2:B239,"passport",'1. Danh mục năng lực'!H2:H239,"T3") -> 0
A35: plan | B35: =COUNTIF('1. Danh mục năng lực'!B2:B239,"plan") -> 7 | C35: =COUNTIFS('1. Danh mục năng lực'!B2:B239,"plan",'1. Danh mục năng lực'!H2:H239,"T1~*")+COUNTIFS('1. Danh mục năng lực'!B2:B239,"plan",'1. Danh mục năng lực'!H2:H239,"T1") -> 7 | D35: =COUNTIFS('1. Danh mục năng lực'!B2:B239,"plan",'1. Danh mục năng lực'!H2:H239,"T2") -> 0 | E35: =COUNTIFS('1. Danh mục năng lực'!B2:B239,"plan",'1. Danh mục năng lực'!H2:H239,"T3") -> 0
A36: policy | B36: =COUNTIF('1. Danh mục năng lực'!B2:B239,"policy") -> 7 | C36: =COUNTIFS('1. Danh mục năng lực'!B2:B239,"policy",'1. Danh mục năng lực'!H2:H239,"T1~*")+COUNTIFS('1. Danh mục năng lực'!B2:B239,"policy",'1. Danh mục năng lực'!H2:H239,"T1") -> 3 | D36: =COUNTIFS('1. Danh mục năng lực'!B2:B239,"policy",'1. Danh mục năng lực'!H2:H239,"T2") -> 3 | E36: =COUNTIFS('1. Danh mục năng lực'!B2:B239,"policy",'1. Danh mục năng lực'!H2:H239,"T3") -> 1
A37: project | B37: =COUNTIF('1. Danh mục năng lực'!B2:B239,"project") -> 9 | C37: =COUNTIFS('1. Danh mục năng lực'!B2:B239,"project",'1. Danh mục năng lực'!H2:H239,"T1~*")+COUNTIFS('1. Danh mục năng lực'!B2:B239,"project",'1. Danh mục năng lực'!H2:H239,"T1") -> 9 | D37: =COUNTIFS('1. Danh mục năng lực'!B2:B239,"project",'1. Danh mục năng lực'!H2:H239,"T2") -> 0 | E37: =COUNTIFS('1. Danh mục năng lực'!B2:B239,"project",'1. Danh mục năng lực'!H2:H239,"T3") -> 0
A38: registry | B38: =COUNTIF('1. Danh mục năng lực'!B2:B239,"registry") -> 5 | C38: =COUNTIFS('1. Danh mục năng lực'!B2:B239,"registry",'1. Danh mục năng lực'!H2:H239,"T1~*")+COUNTIFS('1. Danh mục năng lực'!B2:B239,"registry",'1. Danh mục năng lực'!H2:H239,"T1") -> 5 | D38: =COUNTIFS('1. Danh mục năng lực'!B2:B239,"registry",'1. Danh mục năng lực'!H2:H239,"T2") -> 0 | E38: =COUNTIFS('1. Danh mục năng lực'!B2:B239,"registry",'1. Danh mục năng lực'!H2:H239,"T3") -> 0
A39: report | B39: =COUNTIF('1. Danh mục năng lực'!B2:B239,"report") -> 4 | C39: =COUNTIFS('1. Danh mục năng lực'!B2:B239,"report",'1. Danh mục năng lực'!H2:H239,"T1~*")+COUNTIFS('1. Danh mục năng lực'!B2:B239,"report",'1. Danh mục năng lực'!H2:H239,"T1") -> 4 | D39: =COUNTIFS('1. Danh mục năng lực'!B2:B239,"report",'1. Danh mục năng lực'!H2:H239,"T2") -> 0 | E39: =COUNTIFS('1. Danh mục năng lực'!B2:B239,"report",'1. Danh mục năng lực'!H2:H239,"T3") -> 0
A40: req | B40: =COUNTIF('1. Danh mục năng lực'!B2:B239,"req") -> 8 | C40: =COUNTIFS('1. Danh mục năng lực'!B2:B239,"req",'1. Danh mục năng lực'!H2:H239,"T1~*")+COUNTIFS('1. Danh mục năng lực'!B2:B239,"req",'1. Danh mục năng lực'!H2:H239,"T1") -> 8 | D40: =COUNTIFS('1. Danh mục năng lực'!B2:B239,"req",'1. Danh mục năng lực'!H2:H239,"T2") -> 0 | E40: =COUNTIFS('1. Danh mục năng lực'!B2:B239,"req",'1. Danh mục năng lực'!H2:H239,"T3") -> 0
A41: search | B41: =COUNTIF('1. Danh mục năng lực'!B2:B239,"search") -> 9 | C41: =COUNTIFS('1. Danh mục năng lực'!B2:B239,"search",'1. Danh mục năng lực'!H2:H239,"T1~*")+COUNTIFS('1. Danh mục năng lực'!B2:B239,"search",'1. Danh mục năng lực'!H2:H239,"T1") -> 9 | D41: =COUNTIFS('1. Danh mục năng lực'!B2:B239,"search",'1. Danh mục năng lực'!H2:H239,"T2") -> 0 | E41: =COUNTIFS('1. Danh mục năng lực'!B2:B239,"search",'1. Danh mục năng lực'!H2:H239,"T3") -> 0
A42: sim | B42: =COUNTIF('1. Danh mục năng lực'!B2:B239,"sim") -> 7 | C42: =COUNTIFS('1. Danh mục năng lực'!B2:B239,"sim",'1. Danh mục năng lực'!H2:H239,"T1~*")+COUNTIFS('1. Danh mục năng lực'!B2:B239,"sim",'1. Danh mục năng lực'!H2:H239,"T1") -> 6 | D42: =COUNTIFS('1. Danh mục năng lực'!B2:B239,"sim",'1. Danh mục năng lực'!H2:H239,"T2") -> 1 | E42: =COUNTIFS('1. Danh mục năng lực'!B2:B239,"sim",'1. Danh mục năng lực'!H2:H239,"T3") -> 0
A43: target | B43: =COUNTIF('1. Danh mục năng lực'!B2:B239,"target") -> 9 | C43: =COUNTIFS('1. Danh mục năng lực'!B2:B239,"target",'1. Danh mục năng lực'!H2:H239,"T1~*")+COUNTIFS('1. Danh mục năng lực'!B2:B239,"target",'1. Danh mục năng lực'!H2:H239,"T1") -> 8 | D43: =COUNTIFS('1. Danh mục năng lực'!B2:B239,"target",'1. Danh mục năng lực'!H2:H239,"T2") -> 0 | E43: =COUNTIFS('1. Danh mục năng lực'!B2:B239,"target",'1. Danh mục năng lực'!H2:H239,"T3") -> 1
...

Sheet 3. Theo vòng đời
A1: Giai đoạn | B1: Nhóm năng lực | C1: Số năng lực | D1: Mô tả | E1: Mã năng lực
A2: 1. Thu thập & phân tích yêu cầu | B2: req, chat, memory, search | C2: 33 | D2: Kỹ sư ra lệnh; tác tử thu thập, phân loại, đối chiếu khả thi với hộ chiếu; câu hỏi gộp cho ô trống; sinh URD/SRS. | E2: memory.compose, memory.compress, memory.retrieve, memory.progress, memory.ledger, memory.error_ledger, memory.forget, memory.summarize_session, search.registry, search.vendor, search.docs_mcp, search.web, search.rank, search.fetch, search.verify_match, search.missing, search.reference_projects, chat.parse_intent, chat.ground, chat.fill_defaults, chat.clarify, chat.restate, chat.orchestrate, chat.report_back, chat.decline, req.elicit, req.classify, req.ground_hw, req.detect_conflict, req.prioritize, req.trace_matrix, req.acceptance, req.change_impact
A3: 2. Tri thức phần cứng | B3: archive, extract, passport, kg, board, view | C3: 63 | D3: Khai phá zip/rar, trích xuất PDF/ảnh/BOM/netlist → fact có nguồn → hộ chiếu chip/board và đồ thị tri thức; hiển thị bản đồ tri thức, nguồn gốc, hỏi–đáp RAG có trích dẫn. | E3: archive.list, archive.unpack, archive.extract_one, archive.query, ingest.classify, ingest.hash_dedupe, ingest.index_text, extract.svd, extract.atdf, extract.edc, extract.header_c, extract.dt_binding, extract.pdf_layout, extract.pdf_register_map, extract.pdf_electrical, extract.pdf_pinout, extract.pdf_errata, extract.pdf_formula, extract.ocr, extract.image_schematic, extract.image_board, extract.image_scope, extract.kicad_netlist, extract.bom, extract.bom_enrich, extract.office, extract.readme_goal, extract.code_constants, passport.import, passport.query, passport.list, passport.diff, passport.upgrade, passport.verify_on_board, passport.export, passport.resolve_address, kg.build, kg.conflicts, kg.impact, kg.neighborhood, kg.review_facts, kg.resolve_conflict, kg.supersede, kg.request, kg.evidence, board.build_passport, board.check_pins, board.constraints, board.propose_fix, board.mark_lab, view.kg_map, view.kg_focus, view.provenance, view.conflict_board, view.coverage_map, view.impact_map, view.rag_ask, view.rag_trace, view.rag_index, view.rag_compare, view.doc_side_by_side, view.timeline, view.export_map
A4: 3. Thiết kế kiến trúc & chi tiết | B4: arch, diagram, plan | C4: 32 | D4: Chọn kiểu kiến trúc, phân rã module, gán tài nguyên phần cứng, ngân sách RAM/thời gian, ADR; vẽ sơ đồ khối/kiến trúc/tuần tự/trạng thái; lập kế hoạch. | E4: plan.define_feature, plan.decompose, plan.create, plan.order, plan.estimate, plan.replan, plan.sufficiency, arch.style_select, arch.decompose, arch.map_hw, arch.memory_budget, arch.timing_budget, arch.interface_spec, arch.state_machine, arch.adr, arch.review, arch.compare, arch.to_plan, diagram.render, diagram.block, diagram.pinmap, diagram.architecture, diagram.sequence, diagram.state, diagram.flow, diagram.timing, diagram.memory_map, diagram.kg_view, diagram.gantt, diagram.from_image, diagram.lint, diagram.sync
A5: 4. Môi trường & hiện thực | B5: env, code, project | C5: 32 | D5: Kiểm tra/cài công cụ (hỏi khi R2+), sinh mã theo module, tích hợp, merge có hoàn tác. | E5: project.create, project.open, project.list, project.clone, project.archive, project.set_target, project.rollback, project.status, project.preferences, env.detect, env.check, env.install, env.guide_install, env.lock, env.install_pack, env.sandbox, code.generate_module, code.modify, code.integrate, code.constant_guard, code.build, code.size, code.static, code.test_host, code.generate_tests, code.self_repair, code.review, code.merge, code.revert, code.annotate, code.docs, code.refactor
A6: 5. Mô phỏng, nạp, gỡ lỗi, đo | B6: discover, sim, target, debug, measure, bench | C6: 40 | D6: Dò board/probe/cổng, ID chip, tốc độ kết nối, quét bus; dựng mô phỏng, nạp/verify qua ISA adapter, thí nghiệm theo chính sách, đo đạc, benchmark. | E6: sim.build_platform, sim.mock_peripheral, sim.model_plant, sim.scenario, sim.run, sim.sweep, sim.compare_hil, target.detect, target.flash, target.reset, target.serial, target.probe_read, target.probe_write, target.erase_fuse, target.diagnose_fault, target.observe, debug.log_stats, debug.ask_at, debug.hypothesize, debug.experiment, debug.save_session, debug.propose_fix, measure.capture_signal, measure.power, measure.sync, bench.run, bench.badge, bench.suggest_skill_fix, discover.ports, discover.probe, discover.chip_id, discover.board_match, discover.bus_scan, discover.link_speed, discover.clock_measure, discover.power, discover.firmware_probe, discover.network, discover.env_hw, discover.auto_setup
A7: 6. Tài liệu, báo cáo, phát hành | B7: doc, report, registry | C7: 21 | D7: Sinh bộ tài liệu chuẩn EAA/EIDE có mục Nguồn, chèn lược đồ, báo cáo kiểm thử/tiến độ, đóng gói .hkp. | E7: registry.search, registry.pull, registry.pack, registry.publish, registry.seed, report.progress, report.export, report.human_ai_matrix, report.explain, doc.generate, doc.section, doc.api_ref, doc.datasheet_summary, doc.bringup_guide, doc.test_report, doc.embed_diagram, doc.style_check, doc.translate, doc.changelog, doc.slides, doc.sync
A8: Xuyên suốt: chính sách tự chủ | B8: policy | C8: 7 | D8: APPROVE/ASK/REJECT theo cổng, cửa sổ hoàn tác, leo thang, dừng khẩn, học ngưỡng. | E8: policy.decide, policy.permit, policy.undo_window, policy.escalate, policy.emergency_stop, policy.learn_thresholds, policy.set_autonomy
A9: Xuyên suốt: tự tạo công cụ (self-tooling) | B9: tool | C9: 10 | D9: Khi thiếu năng lực phù hợp, tác tử tự đặc tả, viết công cụ Python, test trong sandbox, chạy theo chính sách rủi ro suy ra từ hiệu ứng, đăng ký thành năng lực tạm và thăng cấp sau khi chứng minh — năng lực gốc sinh ra năng lực khác. | E9: tool.need, tool.search, tool.write, tool.test, tool.run, tool.register, tool.repair, tool.promote, tool.compose, tool.deprecate
