Workbook

Sheet Tổng quan
A1: GEDITOR FOR MACOS — TỔNG HỢP TÍNH NĂNG SẢN PHẨM
A2: Trình soạn thảo file hàng Gigabyte · CÔNG TY TNHH MOBILUCK · code247.ai · 20/08/2026 · Nguồn: bộ tài liệu thiết kế v2.0 (SRS v1.9)
A4: CON SỐ TỔNG (tự đếm từ các sheet — luôn khớp danh mục)
A5: Tổng tính năng (FR) | B5: =COUNTA('Danh mục tính năng (FR)'!A3:A500) -> 137
A6: Tổng cam kết chất lượng (NFR) | B6: =COUNTA('Cam kết chất lượng (NFR)'!A3:A500) -> 50
A7: Tính năng P0 — chặn phát hành | B7: =COUNTIF('Danh mục tính năng (FR)'!E:E,"P0") -> 38
A8: Tính năng P1 | B8: =COUNTIF('Danh mục tính năng (FR)'!E:E,"P1") -> 48
A9: Tính năng P2 (kể cả các Pack) | B9: =COUNTIF('Danh mục tính năng (FR)'!E:E,"P2") -> 51
A10: Nhóm tính năng | B10: 15
A12: CHUỖI GIÁ TRỊ DỮ LIỆU — 8 mắt xích khép kín trên MỘT ứng dụng
A13: 1 · MỞ | C13: File text/CSV/JSONL hàng Gigabyte — Excel và editor thường mở không nổi (KPI: 1 GB ≤ 8 giây, cuộn 60 fps)
A14: 2 · NHÌN | C14: Data Profile 1 giây biết ngay: kiểu, %null, distinct, outlier, phân bố
A15: 3 · HỎI | C15: Filter không cần SQL → Pivot kéo-thả sinh SQL → Workbench DuckDB đầy đủ
A16: 4 · HIỂU | C16: Quick Charts + Data Mining: bất thường có giải thích, phân cụm, dự báo so baseline
A17: 5 · LÀM SẠCH | C17: Bàn làm sạch một cửa: ngày/số/null/trùng mờ — preview, 1 undo, báo cáo
A18: 6 · TRÌNH BÀY | C18: Report .greport.md: báo cáo là văn bản — diff/Git/batch 63 tỉnh/xuất PDF
A19: 7 · TRI THỨC | C19: Knowledge Pack: Graph query + soạn + refactor, BM25 RAG Lab, context package GraphRAG
A20: 8 · TỰ ĐỘNG HÓA | C20: Macro, Recipe, CLI, và Agent BYOK — nói tiếng Việt, máy làm, người duyệt
A22: BẤT BIẾN THIẾT KẾ — những lời hứa có test case bảo vệ
A23: ✓ | C23: Nhẹ tuyệt đối: khởi động ≤ 500 ms · RAM nghỉ ≤ 80 MB · các Pack zero-cost khi tắt (chênh ≤ 1%)
A24: ✓ | C24: Không mất dữ liệu: lưu atomic, snapshot 10 giây, khôi phục sau sự cố — mọi biến đổi hàng loạt là 1 bước undo
A25: ✓ | C25: Phân tích chỉ-đọc: query/chart/mining/report không bao giờ sửa file nguồn (kiểm checksum trong test)
A26: ✓ | C26: Riêng tư: zero telemetry; Agent BYOK — key trong Keychain, egress duy nhất là provider bạn chọn
A27: ✓ | C27: Giải thích được: mining/graph/BM25 là thuật toán cổ điển tự cài đặt, tất định, kèm khối Phương pháp — không black-box, không dependency ML
A28: ✓ | C28: Tiếng Việt hạng nhất: IME Telex/EVKey là tiêu chí CHẶN PHÁT HÀNH; sửa mojibake TCVN3/VNI; tokenizer âm tiết Việt
A30: 15 NHÓM TÍNH NĂNG (đếm tự động theo nhóm)
A31: Nhóm | B31: Số FR | C31: Một câu về nhóm
A32: Soạn thảo lõi | B32: =COUNTIF('Danh mục tính năng (FR)'!B:B,"Soạn thảo lõi") -> 18 | C32: Multi-caret, cột, sắp xếp, khử trùng lặp — cỗ máy xử lý dòng
A33: Tìm kiếm & thay thế | B33: =COUNTIF('Danh mục tính năng (FR)'!B:B,"Tìm kiếm & thay thế") -> 11 | C33: Regex PCRE2 công nghiệp, Mark lọc dòng, Find-in-Files dry-run
A34: Bảng mã & tiếng Việt | B34: =COUNTIF('Danh mục tính năng (FR)'!B:B,"Bảng mã & tiếng Việt") -> 7 | C34: Sửa mojibake, TCVN3/VNI, NFC/NFD, ký tự ẩn
A35: Tài liệu & file lớn | B35: =COUNTIF('Danh mục tính năng (FR)'!B:B,"Tài liệu & file lớn") -> 14 | C35: Tab/phiên/snapshot, Large File Mode hàng GB, theo dõi log
A36: CSV first-class | B36: =COUNTIF('Danh mục tính năng (FR)'!B:B,"CSV first-class") -> 8 | C36: Rainbow, Table view song song, thao tác cột an toàn
A37: Định dạng & ngôn ngữ | B37: =COUNTIF('Danh mục tính năng (FR)'!B:B,"Định dạng & ngôn ngữ") -> 8 | C37: Tree-sitter, UDL, folding, JSON/XML/Markdown
A38: Tự động hóa | B38: =COUNTIF('Danh mục tính năng (FR)'!B:B,"Tự động hóa") -> 6 | C38: Macro batch, JavaScript, Text Filter, CLI geditor
A39: Hệ sinh thái plugin | B39: =COUNTIF('Danh mục tính năng (FR)'!B:B,"Hệ sinh thái plugin") -> 5 | C39: XPC cách ly, ký số, Plugin Manager
A40: Giao diện & cá nhân hóa | B40: =COUNTIF('Danh mục tính năng (FR)'!B:B,"Giao diện & cá nhân hóa") -> 5 | C40: Theme, Shortcut Mapper preset Notepad++, i18n
A41: Làm sạch & chuẩn hóa | B41: =COUNTIF('Danh mục tính năng (FR)'!B:B,"Làm sạch & chuẩn hóa") -> 6 | C41: Chuẩn hóa ngày/số, null, Data Profile, Recipe
A42: Truy vấn & phân tích | B42: =COUNTIF('Danh mục tính năng (FR)'!B:B,"Truy vấn & phân tích") -> 6 | C42: SQL Workbench, Filter, Pivot sinh SQL, Quick Charts
A43: Visualization Report | B43: =COUNTIF('Danh mục tính năng (FR)'!B:B,"Visualization Report") -> 6 | C43: .greport.md — báo cáo là văn bản, xuất HTML/PDF
A44: Data Mining | B44: =COUNTIF('Danh mục tính năng (FR)'!B:B,"Data Mining") -> 6 | C44: Bất thường, phân cụm, Apriori, dự báo, tương quan, text
...

Sheet Danh mục tính năng (FR)
A1: DANH MỤC 137 TÍNH NĂNG — nguồn: SRS MBL-SRS-GEDIT-001 v1.9
A2: Mã | B2: Nhóm tính năng | C2: Tên tính năng | D2: Mô tả | E2: Ưu tiên | F2: Phase
A3: FR-CORE-001 | B3: Soạn thảo lõi | C3: Multi-caret / multi-selection | D3: Cho phép đặt nhiều con trỏ đồng thời bằng Cmd+Click; Cmd+D chọn lần xuất hiện kế tiếp của từ/vùng chọn; mọi thao tác gõ, xóa, dán áp dụng đồng thời trên tất cả caret. | E3: P0 | F3: 1
A4: FR-CORE-002 | B4: Soạn thảo lõi | C4: Chế độ chọn cột (Column mode) | D4: Chọn khối chữ nhật bằng Option+kéo chuột hoặc Option+Cmd+phím mũi tên; hỗ trợ gõ, xóa, dán theo cột; dán khối cột vào vị trí caret giữ đúng hình chữ nhật. | E4: P0 | F4: 1
A5: FR-CORE-003 | B5: Soạn thảo lõi | C5: Column Editor | D5: Chèn văn bản cố định hoặc dãy số tăng dần (thập phân/hex/octal/binary, bước nhảy, số chữ số đệm 0) và dãy ngày tăng dần vào mọi dòng của vùng chọn cột. | E5: P0 | F5: 1
A6: FR-CORE-004 | B6: Soạn thảo lõi | C6: Undo/Redo không giới hạn | D6: Lịch sử undo không giới hạn trong phiên (giới hạn bởi bộ nhớ), gom nhóm theo thao tác logic, được bảo toàn sau khi lưu file. | E6: P0 | F6: 1
A7: FR-CORE-005 | B7: Soạn thảo lõi | C7: Sắp xếp dòng | D7: Sort tăng/giảm theo: từ điển (có/không phân biệt hoa thường), số nguyên, số thực, natural sort; sort theo cột thứ N với delimiter chỉ định. | E7: P0 | F7: 1
A8: FR-CORE-006 | B8: Soạn thảo lõi | C8: Khử trùng lặp dòng | D8: Xóa dòng trùng lặp trên toàn tài liệu hoặc chỉ các dòng trùng liên tiếp; tùy chọn giữ lần xuất hiện đầu/cuối. | E8: P0 | F8: 1
A9: FR-CORE-007 | B9: Soạn thảo lõi | C9: Thao tác dòng | D9: Join lines, split line theo độ dài/ký tự, move line up/down, duplicate line/selection, đảo ngược thứ tự dòng. | E9: P0 | F9: 1
A10: FR-CORE-008 | B10: Soạn thảo lõi | C10: Thao tác khoảng trắng | D10: Trim khoảng trắng đầu/cuối/cả hai phía; xóa dòng trống (kể cả dòng chỉ chứa khoảng trắng); nén nhiều dòng trống liên tiếp thành một; tùy chọn trim-on-save theo loại file. | E10: P0 | F10: 1
A11: FR-CORE-009 | B11: Soạn thảo lõi | C11: Chuyển đổi TAB ↔ Space | D11: Chuyển đổi hai chiều theo tab width hiện hành; cấu hình tab/space và độ rộng theo từng ngôn ngữ. | E11: P0 | F11: 1
A12: FR-CORE-010 | B12: Soạn thảo lõi | C12: Chuyển đổi hoa/thường | D12: UPPERCASE, lowercase, Proper Case, Sentence case, iNVERT, ranDOM; bổ sung chuyển đổi camelCase / snake_case / kebab-case. | E12: P1 | F12: 1
A13: FR-CORE-011 | B13: Soạn thảo lõi | C13: Tự động thụt lề | D13: Giữ indent dòng trước; smart indent theo cấu trúc cú pháp từ tree-sitter cho ngôn ngữ được hỗ trợ. | E13: P1 | F13: 1
... A139: FR-AGT-1010 | B139: Agent Pack (BYOK) | C139: Đóng gói Agent Pack | D139: Toàn bộ phát hành như MỘT plugin riêng (tách khỏi Knowledge Pack): zero-cost khi tắt; hoạt động hoàn toàn offline khi dùng Ollama/local endpoint. | E139: P2 | F139: 5

Sheet Cam kết chất lượng (NFR)
A1: 50 CAM KẾT CHẤT LƯỢNG — đo được, có test case chặn phát hành
A2: Mã | B2: Nhóm | C2: Chỉ tiêu | D2: Mức cam kết | E2: Ưu tiên
A3: NFR-PERF-01 | B3: Hiệu năng | C3: Khởi động nguội | D3: ≤ 500 ms trên Apple Silicon (M1 trở lên); ≤ 1 giây trên Intel (i5 2019); đo tới khi cửa sổ nhận thao tác gõ. | E3: P0
A4: NFR-PERF-02 | B4: Hiệu năng | C4: Mở file 100 MB | D4: ≤ 2 giây tới trạng thái tương tác được (gõ, cuộn); highlight có thể hoàn tất bất đồng bộ sau đó. | E4: P0
A5: NFR-PERF-03 | B5: Hiệu năng | C5: Mở file 1 GB (Large File Mode) | D5: ≤ 8 giây tới tương tác; cuộn duy trì 60 fps; các thao tác dòng cơ bản không treo UI. | E5: P0
A6: NFR-PERF-04 | B6: Hiệu năng | C6: Độ trễ gõ phím | D6: ≤ 16 ms (p95) từ nhấn phím tới hiển thị, kể cả với tài liệu 100 MB và IME tiếng Việt. | E6: P0
A7: NFR-PERF-05 | B7: Hiệu năng | C7: Bộ nhớ | D7: ≤ 80 MB RAM khi idle với 1 tab văn bản nhỏ; tiêu thụ bộ nhớ với file lớn ≤ 1,5 lần kích thước file (nhờ mmap có thể thấp hơn nhiều). | E7: P1
A8: NFR-PERF-06 | B8: Hiệu năng | C8: Find in Files | D8: Quét 10.000 file tận dụng toàn bộ core CPU (scale gần tuyến tính theo số core); luôn có tiến trình và hủy được trong ≤ 200 ms. | E8: P0
A9: NFR-PERF-07 | B9: Hiệu năng | C9: Năng lượng | D9: Mức "Energy Impact: Low" trong Activity Monitor khi idle; không polling nền; dùng FSEvents/Dispatch Source thay vì vòng lặp kiểm tra. | E9: P1
A10: NFR-PERF-08 | B10: Hiệu năng | C10: Regex quy mô lớn | D10: Thay thế 1 triệu kết quả khớp trên file 100 MB hoàn tất ≤ 30 giây, có tiến trình, hủy được, và undo được trong một bước. | E10: P1
A11: NFR-REL-01 | B11: Độ tin cậy | C11: Không mất dữ liệu chưa lưu | D11: Sau crash, kill -9 hoặc mất điện, 100% nội dung chưa lưu được khôi phục từ snapshot ở lần mở kế tiếp (mất tối đa 1 chu kỳ autosave). | E11: P0
A12: NFR-REL-02 | B12: Độ tin cậy | C12: Ghi file an toàn | D12: Mọi thao tác lưu là atomic (ghi file tạm rồi rename); không bao giờ để lại file đích hỏng dở dang; bảo toàn metadata, quyền, extended attributes, tag Finder. | E12: P0
A13: NFR-REL-03 | B13: Độ tin cậy | C13: Ổn định | D13: Tỷ lệ phiên không crash ≥ 99,8%; crash reporter opt-in gửi kèm ngữ cảnh tối thiểu, không kèm nội dung tài liệu. | E13: P0
... A52: NFR-AGT-04 | B52: Agent Pack | C52: Phản hồi & hủy | D52: Token đầu tiên hiển thị dạng streaming; hủy phiên đáp ứng ≤ 200 ms; UI editor không bao giờ bị khóa khi agent đang chạy. | E52: P2

Sheet Lộ trình 5 Phase
A1: LỘ TRÌNH PHÁT HÀNH — mỗi tầng đứng trên tầng trước, không phá KPI
A2: Phase | B2: Chủ đề | C2: Tính năng tiêu biểu | D2: Số FR* | E2: FR P0*
A3: 1 | B3: Editor Gigabyte — nền tảng | C3: Mở 1 GB ≤ 8 giây, multi-caret/cột, regex PCRE2 an toàn, Mark lọc dòng, sửa mojibake tiếng Việt (TCVN3/VNI), Large File Mode, macro + CLI, IME Telex/EVKey chặn phát hành | D3: =COUNTIF('Danh mục tính năng (FR)'!F:F,"1")+COUNTIF('Danh mục tính năng (FR)'!F:F,"*–1*")+COUNTIF('Danh mục tính năng (FR)'!F:F,"1–*") -> 51 | E3: =COUNTIFS('Danh mục tính năng (FR)'!F:F,"1",'Danh mục tính năng (FR)'!E:E,"P0") -> 30
A4: 2 | B4: Dữ liệu văn phòng | C4: CSV Table view song song, Bàn làm sạch ⌘⇧L (ngày/số/null không cần regex), Data Profile, Filter theo cột, Cleaning Recipe, UDL | D4: =COUNTIF('Danh mục tính năng (FR)'!F:F,"2")+COUNTIF('Danh mục tính năng (FR)'!F:F,"*–2*")+COUNTIF('Danh mục tính năng (FR)'!F:F,"2–*") -> 34 | E4: =COUNTIFS('Danh mục tính năng (FR)'!F:F,"2",'Danh mục tính năng (FR)'!E:E,"P0") -> 4
A5: 3 | B5: Phân tích & trình bày | C5: Query Workbench SQL + Pivot kéo-thả sinh SQL, Quick Charts, Data Mining (bất thường/phân cụm/dự báo), Report .greport.md xuất HTML/PDF, plugin native | D5: =COUNTIF('Danh mục tính năng (FR)'!F:F,"3")+COUNTIF('Danh mục tính năng (FR)'!F:F,"*–3*")+COUNTIF('Danh mục tính năng (FR)'!F:F,"3–*") -> 26 | E5: =COUNTIFS('Danh mục tính năng (FR)'!F:F,"3",'Danh mục tính năng (FR)'!E:E,"P0") -> 0
A6: 4 | B6: Knowledge Pack (plugin) | C6: JSONL 1 GB, Graph query openCypher→SQL, PageRank/Louvain, soạn Graph trực quan + refactor, schema validation, BM25 Retrieval Lab, context package GraphRAG | D6: =COUNTIF('Danh mục tính năng (FR)'!F:F,"4")+COUNTIF('Danh mục tính năng (FR)'!F:F,"*–4*")+COUNTIF('Danh mục tính năng (FR)'!F:F,"4–*") -> 24 | E6: =COUNTIFS('Danh mục tính năng (FR)'!F:F,"4",'Danh mục tính năng (FR)'!E:E,"P0") -> 0
A7: 5 | B7: Agent Pack (plugin BYOK) | C7: Nhập key (Keychain) + chọn model, agent thao tác file GB qua tools, cổng diff duyệt, hoàn tác cả phiên, đồng hồ chi phí, lệnh lặp không tốn token | D7: =COUNTIF('Danh mục tính năng (FR)'!F:F,"5")+COUNTIF('Danh mục tính năng (FR)'!F:F,"*–5*")+COUNTIF('Danh mục tính năng (FR)'!F:F,"5–*") -> 10 | E7: =COUNTIFS('Danh mục tính năng (FR)'!F:F,"5",'Danh mục tính năng (FR)'!E:E,"P0") -> 0
B8: * Phase ghi dạng khoảng (1–2, 3–4) được đếm ở phase bắt đầu và phase kết thúc — con số mang tính tham chiếu.
